Workbook

Sheet 販売１
B1: 予算表
B3: 期：
B5: 部署：
B7: 項目 | J7: 年間計 | P7: １０月 | U7: １１月 | Z7: １２月 | AE7: １０月～１２月合計 | AK7: １月 | AP7: ２月 | AU7: ３月 | AZ7: １月～３月合計 | BF7: ４月 | BK7: ５月 | BP7: ６月 | BU7: ４月～６月合計 | CA7: ７月 | CF7: ８月 | CK7: ９月 | CP7: ７月～９月合計
A8: LineNo
J9: 計画 | K9: 前年実績 | L9: 指標 | M9: 差 | N9: 前年比 | P9: 計画 | Q9: 前年実績 | R9: 指標 | S9: 差 | T9: 前年比 | U9: 計画 | V9: 前年実績 | W9: 指標 | X9: 差 | Y9: 前年比 | Z9: 計画 | AA9: 前年実績 | AB9: 指標 | AC9: 差 | AD9: 前年比 | AE9: 計画 | AF9: 前年実績 | AG9: 指標 | AH9: 差 | AI9: 前年比 | AK9: 計画 | AL9: 前年実績 | AM9: 指標 | AN9: 差 | AO9: 前年比 | AP9: 計画 | AQ9: 前年実績 | AR9: 指標 | AS9: 差 | AT9: 前年比 | AU9: 計画 | AV9: 前年実績 | AW9: 指標 | AX9: 差 | AY9: 前年比 | AZ9: 計画 | BA9: 前年実績 | BB9: 指標 | BC9: 差 | BD9: 前年比 | BF9: 計画 | BG9: 前年実績 | BH9: 指標 | BI9: 差 | BJ9: 前年比 | BK9: 計画 | BL9: 前年実績 | BM9: 指標 | BN9: 差 | BO9: 前年比 | BP9: 計画 | BQ9: 前年実績 | BR9: 指標 | BS9: 差 | BT9: 前年比 | BU9: 計画 | BV9: 前年実績 | BW9: 指標 | BX9: 差 | BY9: 前年比 | CA9: 計画 | CB9: 前年実績 | CC9: 指標 | CD9: 差 | CE9: 前年比 | CF9: 計画 | CG9: 前年実績 | CH9: 指標 | CI9: 差 | CJ9: 前年比 | CK9: 計画 | CL9: 前年実績 | CM9: 指標 | CN9: 差 | CO9: 前年比 | CP9: 計画 | CQ9: 前年実績 | CR9: 指標 | CS9: 差 | CT9: 前年比
A10: 1 | B10: 営業スタッフ数 | J10: =SUM(P10,U10,Z10,AK10,AP10,AU10,BF10,BK10,BP10,CA10,CF10,CK10) -> 0 | K10: =SUM(Q10,V10,AA10,AL10,AQ10,AV10,BG10,BL10,BQ10,CB10,CG10,CL10) -> 0 | L10: =SUM(R10,W10,AB10,AM10,AR10,AW10,BH10,BM10,BR10,CC10,CH10,CM10) -> 0 | M10: =SUM(S10,X10,AC10,AN10,AS10,AX10,BI10,BN10,BS10,CD10,CI10,CN10) -> 0 | N10: =SUM(T10,Y10,AD10,AO10,AT10,AY10,BJ10,BO10,BT10,CE10,CJ10,CO10) -> 0 | S10: =P10-Q10 -> 0 | X10: =U10-V10 -> 0 | AD10: =AA10-AB10 -> 0 | AH10: =AE10-AF10 -> 0 | AN10: =AK10-AL10 -> 0 | AS10: =AP10-AQ10 -> 0 | AX10: =AU10-AV10 -> 0 | BC10: =AZ10-BA10 -> 0 | BI10: =BF10-BG10 -> 0 | BN10: =BK10-BL10 -> 0 | BS10: =BP10-BQ10 -> 0 | BX10: =BU10-BV10 -> 0 | CD10: =CA10-CB10 -> 0 | CI10: =CF10-CG10 -> 0 | CN10: =CK10-CL10 -> 0 | CS10: =CP10-CQ10 -> 0
A11: 2 | B11: 自新直顧客数 | J11: =SUM(P11,U11,Z11,AK11,AP11,AU11,BF11,BK11,BP11,CA11,CF11,CK11) -> 0 | K11: =SUM(Q11,V11,AA11,AL11,AQ11,AV11,BG11,BL11,BQ11,CB11,CG11,CL11) -> 0 | L11: =SUM(R11,W11,AB11,AM11,AR11,AW11,BH11,BM11,BR11,CC11,CH11,CM11) -> 0 | M11: =SUM(S11,X11,AC11,AN11,AS11,AX11,BI11,BN11,BS11,CD11,CI11,CN11) -> 0 | N11: =SUM(T11,Y11,AD11,AO11,AT11,AY11,BJ11,BO11,BT11,CE11,CJ11,CO11) -> 0 | S11: =P11-Q11 -> 0 | X11: =U11-V11 -> 0 | AD11: =AA11-AB11 -> 0 | AH11: =AE11-AF11 -> 0 | AN11: =AK11-AL11 -> 0 | AS11: =AP11-AQ11 -> 0 | AX11: =AU11-AV11 -> 0 | BC11: =AZ11-BA11 -> 0 | BI11: =BF11-BG11 -> 0 | BN11: =BK11-BL11 -> 0 | BS11: =BP11-BQ11 -> 0 | BX11: =BU11-BV11 -> 0 | CD11: =CA11-CB11 -> 0 | CI11: =CF11-CG11 -> 0 | CN11: =CK11-CL11 -> 0 | CS11: =CP11-CQ11 -> 0
A12: 3 | B12: 顧客代替台数 | J12: =SUM(P12,U12,Z12,AK12,AP12,AU12,BF12,BK12,BP12,CA12,CF12,CK12) -> 0 | K12: =SUM(Q12,V12,AA12,AL12,AQ12,AV12,BG12,BL12,BQ12,CB12,CG12,CL12) -> 0 | L12: =SUM(R12,W12,AB12,AM12,AR12,AW12,BH12,BM12,BR12,CC12,CH12,CM12) -> 0 | M12: =SUM(S12,X12,AC12,AN12,AS12,AX12,BI12,BN12,BS12,CD12,CI12,CN12) -> 0 | N12: =SUM(T12,Y12,AD12,AO12,AT12,AY12,BJ12,BO12,BT12,CE12,CJ12,CO12) -> 0 | S12: =P12-Q12 -> 0 | X12: =U12-V12 -> 0 | AD12: =AA12-AB12 -> 0 | AH12: =AE12-AF12 -> 0 | AN12: =AK12-AL12 -> 0 | AS12: =AP12-AQ12 -> 0 | AX12: =AU12-AV12 -> 0 | BC12: =AZ12-BA12 -> 0 | BI12: =BF12-BG12 -> 0 | BN12: =BK12-BL12 -> 0 | BS12: =BP12-BQ12 -> 0 | BX12: =BU12-BV12 -> 0 | CD12: =CA12-CB12 -> 0 | CI12: =CF12-CG12 -> 0 | CN12: =CK12-CL12 -> 0 | CS12: =CP12-CQ12 -> 0
A13: 4 | B13: 自中直顧客数 | J13: =SUM(P13,U13,Z13,AK13,AP13,AU13,BF13,BK13,BP13,CA13,CF13,CK13) -> 0 | K13: =SUM(Q13,V13,AA13,AL13,AQ13,AV13,BG13,BL13,BQ13,CB13,CG13,CL13) -> 0 | L13: =SUM(R13,W13,AB13,AM13,AR13,AW13,BH13,BM13,BR13,CC13,CH13,CM13) -> 0 | M13: =SUM(S13,X13,AC13,AN13,AS13,AX13,BI13,BN13,BS13,CD13,CI13,CN13) -> 0 | N13: =SUM(T13,Y13,AD13,AO13,AT13,AY13,BJ13,BO13,BT13,CE13,CJ13,CO13) -> 0 | S13: =P13-Q13 -> 0 | X13: =U13-V13 -> 0 | AD13: =AA13-AB13 -> 0 | AH13: =AE13-AF13 -> 0 | AN13: =AK13-AL13 -> 0 | AS13: =AP13-AQ13 -> 0 | AX13: =AU13-AV13 -> 0 | BC13: =AZ13-BA13 -> 0 | BI13: =BF13-BG13 -> 0 | BN13: =BK13-BL13 -> 0 | BS13: =BP13-BQ13 -> 0 | BX13: =BU13-BV13 -> 0 | CD13: =CA13-CB13 -> 0 | CI13: =CF13-CG13 -> 0 | CN13: =CK13-CL13 -> 0 | CS13: =CP13-CQ13 -> 0
A14: 5 | B14: サービス直人員 | J14: =SUM(P14,U14,Z14,AK14,AP14,AU14,BF14,BK14,BP14,CA14,CF14,CK14) -> 0 | K14: =SUM(Q14,V14,AA14,AL14,AQ14,AV14,BG14,BL14,BQ14,CB14,CG14,CL14) -> 0 | L14: =SUM(R14,W14,AB14,AM14,AR14,AW14,BH14,BM14,BR14,CC14,CH14,CM14) -> 0 | M14: =SUM(S14,X14,AC14,AN14,AS14,AX14,BI14,BN14,BS14,CD14,CI14,CN14) -> 0 | N14: =SUM(T14,Y14,AD14,AO14,AT14,AY14,BJ14,BO14,BT14,CE14,CJ14,CO14) -> 0 | S14: =P14-Q14 -> 0 | X14: =U14-V14 -> 0 | AD14: =AA14-AB14 -> 0 | AH14: =AE14-AF14 -> 0 | AN14: =AK14-AL14 -> 0 | AS14: =AP14-AQ14 -> 0 | AX14: =AU14-AV14 -> 0 | BC14: =AZ14-BA14 -> 0 | BI14: =BF14-BG14 -> 0 | BN14: =BK14-BL14 -> 0 | BS14: =BP14-BQ14 -> 0 | BX14: =BU14-BV14 -> 0 | CD14: =CA14-CB14 -> 0 | CI14: =CF14-CG14 -> 0 | CN14: =CK14-CL14 -> 0 | CS14: =CP14-CQ14 -> 0
A15: 6 | B15: サービス管理顧客数 | J15: =SUM(P15,U15,Z15,AK15,AP15,AU15,BF15,BK15,BP15,CA15,CF15,CK15) -> 0 | K15: =SUM(Q15,V15,AA15,AL15,AQ15,AV15,BG15,BL15,BQ15,CB15,CG15,CL15) -> 0 | L15: =SUM(R15,W15,AB15,AM15,AR15,AW15,BH15,BM15,BR15,CC15,CH15,CM15) -> 0 | M15: =SUM(S15,X15,AC15,AN15,AS15,AX15,BI15,BN15,BS15,CD15,CI15,CN15) -> 0 | N15: =SUM(T15,Y15,AD15,AO15,AT15,AY15,BJ15,BO15,BT15,CE15,CJ15,CO15) -> 0 | S15: =P15-Q15 -> 0 | X15: =U15-V15 -> 0 | AD15: =AA15-AB15 -> 0 | AH15: =AE15-AF15 -> 0 | AN15: =AK15-AL15 -> 0 | AS15: =AP15-AQ15 -> 0 | AX15: =AU15-AV15 -> 0 | BC15: =AZ15-BA15 -> 0 | BI15: =BF15-BG15 -> 0 | BN15: =BK15-BL15 -> 0 | BS15: =BP15-BQ15 -> 0 | BX15: =BU15-BV15 -> 0 | CD15: =CA15-CB15 -> 0 | CI15: =CF15-CG15 -> 0 | CN15: =CK15-CL15 -> 0 | CS15: =CP15-CQ15 -> 0
A16: 7 | B16: 車検対象台数 | J16: =SUM(P16,U16,Z16,AK16,AP16,AU16,BF16,BK16,BP16,CA16,CF16,CK16) -> 0 | K16: =SUM(Q16,V16,AA16,AL16,AQ16,AV16,BG16,BL16,BQ16,CB16,CG16,CL16) -> 0 | L16: =SUM(R16,W16,AB16,AM16,AR16,AW16,BH16,BM16,BR16,CC16,CH16,CM16) -> 0 | M16: =SUM(S16,X16,AC16,AN16,AS16,AX16,BI16,BN16,BS16,CD16,CI16,CN16) -> 0 | N16: =SUM(T16,Y16,AD16,AO16,AT16,AY16,BJ16,BO16,BT16,CE16,CJ16,CO16) -> 0 | S16: =P16-Q16 -> 0 | X16: =U16-V16 -> 0 | AD16: =AA16-AB16 -> 0 | AH16: =AE16-AF16 -> 0 | AN16: =AK16-AL16 -> 0 | AS16: =AP16-AQ16 -> 0 | AX16: =AU16-AV16 -> 0 | BC16: =AZ16-BA16 -> 0 | BI16: =BF16-BG16 -> 0 | BN16: =BK16-BL16 -> 0 | BS16: =BP16-BQ16 -> 0 | BX16: =BU16-BV16 -> 0 | CD16: =CA16-CB16 -> 0 | CI16: =CF16-CG16 -> 0 | CN16: =CK16-CL16 -> 0 | CS16: =CP16-CQ16 -> 0
A17: 8 | C17: 内初回車検対象台数 | J17: =SUM(P17,U17,Z17,AK17,AP17,AU17,BF17,BK17,BP17,CA17,CF17,CK17) -> 0 | K17: =SUM(Q17,V17,AA17,AL17,AQ17,AV17,BG17,BL17,BQ17,CB17,CG17,CL17) -> 0 | L17: =SUM(R17,W17,AB17,AM17,AR17,AW17,BH17,BM17,BR17,CC17,CH17,CM17) -> 0 | M17: =SUM(S17,X17,AC17,AN17,AS17,AX17,BI17,BN17,BS17,CD17,CI17,CN17) -> 0 | N17: =SUM(T17,Y17,AD17,AO17,AT17,AY17,BJ17,BO17,BT17,CE17,CJ17,CO17) -> 0 | S17: =P17-Q17 -> 0 | X17: =U17-V17 -> 0 | AD17: =AA17-AB17 -> 0 | AH17: =AE17-AF17 -> 0 | AN17: =AK17-AL17 -> 0 | AS17: =AP17-AQ17 -> 0 | AX17: =AU17-AV17 -> 0 | BC17: =AZ17-BA17 -> 0 | BI17: =BF17-BG17 -> 0 | BN17: =BK17-BL17 -> 0 | BS17: =BP17-BQ17 -> 0 | BX17: =BU17-BV17 -> 0 | CD17: =CA17-CB17 -> 0 | CI17: =CF17-CG17 -> 0 | CN17: =CK17-CL17 -> 0 | CS17: =CP17-CQ17 -> 0
A18: 9 | B18: 初回車検入庫 | J18: =SUM(P18,U18,Z18,AK18,AP18,AU18,BF18,BK18,BP18,CA18,CF18,CK18) -> 0 | K18: =SUM(Q18,V18,AA18,AL18,AQ18,AV18,BG18,BL18,BQ18,CB18,CG18,CL18) -> 0 | L18: =SUM(R18,W18,AB18,AM18,AR18,AW18,BH18,BM18,BR18,CC18,CH18,CM18) -> 0 | M18: =SUM(S18,X18,AC18,AN18,AS18,AX18,BI18,BN18,BS18,CD18,CI18,CN18) -> 0 | N18: =SUM(T18,Y18,AD18,AO18,AT18,AY18,BJ18,BO18,BT18,CE18,CJ18,CO18) -> 0 | S18: =P18-Q18 -> 0 | X18: =U18-V18 -> 0 | AD18: =AA18-AB18 -> 0 | AH18: =AE18-AF18 -> 0 | AN18: =AK18-AL18 -> 0 | AS18: =AP18-AQ18 -> 0 | AX18: =AU18-AV18 -> 0 | BC18: =AZ18-BA18 -> 0 | BI18: =BF18-BG18 -> 0 | BN18: =BK18-BL18 -> 0 | BS18: =BP18-BQ18 -> 0 | BX18: =BU18-BV18 -> 0 | CD18: =CA18-CB18 -> 0 | CI18: =CF18-CG18 -> 0 | CN18: =CK18-CL18 -> 0 | CS18: =CP18-CQ18 -> 0
A19: 10 | B19: 有償入庫台数 | J19: =SUM(P19,U19,Z19,AK19,AP19,AU19,BF19,BK19,BP19,CA19,CF19,CK19) -> 0 | K19: =SUM(Q19,V19,AA19,AL19,AQ19,AV19,BG19,BL19,BQ19,CB19,CG19,CL19) -> 0 | L19: =SUM(R19,W19,AB19,AM19,AR19,AW19,BH19,BM19,BR19,CC19,CH19,CM19) -> 0 | M19: =SUM(S19,X19,AC19,AN19,AS19,AX19,BI19,BN19,BS19,CD19,CI19,CN19) -> 0 | N19: =SUM(T19,Y19,AD19,AO19,AT19,AY19,BJ19,BO19,BT19,CE19,CJ19,CO19) -> 0 | S19: =P19-Q19 -> 0 | X19: =U19-V19 -> 0 | AD19: =AA19-AB19 -> 0 | AH19: =AE19-AF19 -> 0 | AN19: =AK19-AL19 -> 0 | AS19: =AP19-AQ19 -> 0 | AX19: =AU19-AV19 -> 0 | BC19: =AZ19-BA19 -> 0 | BI19: =BF19-BG19 -> 0 | BN19: =BK19-BL19 -> 0 | BS19: =BP19-BQ19 -> 0 | BX19: =BU19-BV19 -> 0 | CD19: =CA19-CB19 -> 0 | CI19: =CF19-CG19 -> 0 | CN19: =CK19-CL19 -> 0 | CS19: =CP19-CQ19 -> 0
A20: 11 | B20: 新規獲得件数 | J20: =SUM(P20,U20,Z20,AK20,AP20,AU20,BF20,BK20,BP20,CA20,CF20,CK20) -> 0 | K20: =SUM(Q20,V20,AA20,AL20,AQ20,AV20,BG20,BL20,BQ20,CB20,CG20,CL20) -> 0 | L20: =SUM(R20,W20,AB20,AM20,AR20,AW20,BH20,BM20,BR20,CC20,CH20,CM20) -> 0 | M20: =SUM(S20,X20,AC20,AN20,AS20,AX20,BI20,BN20,BS20,CD20,CI20,CN20) -> 0 | N20: =SUM(T20,Y20,AD20,AO20,AT20,AY20,BJ20,BO20,BT20,CE20,CJ20,CO20) -> 0 | S20: =P20-Q20 -> 0 | X20: =U20-V20 -> 0 | AD20: =AA20-AB20 -> 0 | AH20: =AE20-AF20 -> 0 | AN20: =AK20-AL20 -> 0 | AS20: =AP20-AQ20 -> 0 | AX20: =AU20-AV20 -> 0 | BC20: =AZ20-BA20 -> 0 | BI20: =BF20-BG20 -> 0 | BN20: =BK20-BL20 -> 0 | BS20: =BP20-BQ20 -> 0 | BX20: =BU20-BV20 -> 0 | CD20: =CA20-CB20 -> 0 | CI20: =CF20-CG20 -> 0 | CN20: =CK20-CL20 -> 0 | CS20: =CP20-CQ20 -> 0
A21: 12 | B21: 継続対象件数 | J21: =SUM(P21,U21,Z21,AK21,AP21,AU21,BF21,BK21,BP21,CA21,CF21,CK21) -> 0 | K21: =SUM(Q21,V21,AA21,AL21,AQ21,AV21,BG21,BL21,BQ21,CB21,CG21,CL21) -> 0 | L21: =SUM(R21,W21,AB21,AM21,AR21,AW21,BH21,BM21,BR21,CC21,CH21,CM21) -> 0 | M21: =SUM(S21,X21,AC21,AN21,AS21,AX21,BI21,BN21,BS21,CD21,CI21,CN21) -> 0 | N21: =SUM(T21,Y21,AD21,AO21,AT21,AY21,BJ21,BO21,BT21,CE21,CJ21,CO21) -> 0 | S21: =P21-Q21 -> 0 | X21: =U21-V21 -> 0 | AD21: =AA21-AB21 -> 0 | AH21: =AE21-AF21 -> 0 | AN21: =AK21-AL21 -> 0 | AS21: =AP21-AQ21 -> 0 | AX21: =AU21-AV21 -> 0 | BC21: =AZ21-BA21 -> 0 | BI21: =BF21-BG21 -> 0 | BN21: =BK21-BL21 -> 0 | BS21: =BP21-BQ21 -> 0 | BX21: =BU21-BV21 -> 0 | CD21: =CA21-CB21 -> 0 | CI21: =CF21-CG21 -> 0 | CN21: =CK21-CL21 -> 0 | CS21: =CP21-CQ21 -> 0
A22: 13 | B22: 継続件数 | J22: =SUM(P22,U22,Z22,AK22,AP22,AU22,BF22,BK22,BP22,CA22,CF22,CK22) -> 0 | K22: =SUM(Q22,V22,AA22,AL22,AQ22,AV22,BG22,BL22,BQ22,CB22,CG22,CL22) -> 0 | L22: =SUM(R22,W22,AB22,AM22,AR22,AW22,BH22,BM22,BR22,CC22,CH22,CM22) -> 0 | M22: =SUM(S22,X22,AC22,AN22,AS22,AX22,BI22,BN22,BS22,CD22,CI22,CN22) -> 0 | N22: =SUM(T22,Y22,AD22,AO22,AT22,AY22,BJ22,BO22,BT22,CE22,CJ22,CO22) -> 0 | S22: =P22-Q22 -> 0 | X22: =U22-V22 -> 0 | AD22: =AA22-AB22 -> 0 | AH22: =AE22-AF22 -> 0 | AN22: =AK22-AL22 -> 0 | AS22: =AP22-AQ22 -> 0 | AX22: =AU22-AV22 -> 0 | BC22: =AZ22-BA22 -> 0 | BI22: =BF22-BG22 -> 0 | BN22: =BK22-BL22 -> 0 | BS22: =BP22-BQ22 -> 0 | BX22: =BU22-BV22 -> 0 | CD22: =CA22-CB22 -> 0 | CI22: =CF22-CG22 -> 0 | CN22: =CK22-CL22 -> 0 | CS22: =CP22-CQ22 -> 0
A23: 14 | B23: 車両保険件数 | J23: =SUM(P23,U23,Z23,AK23,AP23,AU23,BF23,BK23,BP23,CA23,CF23,CK23) -> 0 | K23: =SUM(Q23,V23,AA23,AL23,AQ23,AV23,BG23,BL23,BQ23,CB23,CG23,CL23) -> 0 | L23: =SUM(R23,W23,AB23,AM23,AR23,AW23,BH23,BM23,BR23,CC23,CH23,CM23) -> 0 | M23: =SUM(S23,X23,AC23,AN23,AS23,AX23,BI23,BN23,BS23,CD23,CI23,CN23) -> 0 | N23: =SUM(T23,Y23,AD23,AO23,AT23,AY23,BJ23,BO23,BT23,CE23,CJ23,CO23) -> 0 | S23: =P23-Q23 -> 0 | X23: =U23-V23 -> 0 | AD23: =AA23-AB23 -> 0 | AH23: =AE23-AF23 -> 0 | AN23: =AK23-AL23 -> 0 | AS23: =AP23-AQ23 -> 0 | AX23: =AU23-AV23 -> 0 | BC23: =AZ23-BA23 -> 0 | BI23: =BF23-BG23 -> 0 | BN23: =BK23-BL23 -> 0 | BS23: =BP23-BQ23 -> 0 | BX23: =BU23-BV23 -> 0 | CD23: =CA23-CB23 -> 0 | CI23: =CF23-CG23 -> 0 | CN23: =CK23-CL23 -> 0 | CS23: =CP23-CQ23 -> 0
A24: 15 | B24: 収保 | J24: =SUM(P24,U24,Z24,AK24,AP24,AU24,BF24,BK24,BP24,CA24,CF24,CK24) -> 0 | K24: =SUM(Q24,V24,AA24,AL24,AQ24,AV24,BG24,BL24,BQ24,CB24,CG24,CL24) -> 0 | L24: =SUM(R24,W24,AB24,AM24,AR24,AW24,BH24,BM24,BR24,CC24,CH24,CM24) -> 0 | M24: =SUM(S24,X24,AC24,AN24,AS24,AX24,BI24,BN24,BS24,CD24,CI24,CN24) -> 0 | N24: =SUM(T24,Y24,AD24,AO24,AT24,AY24,BJ24,BO24,BT24,CE24,CJ24,CO24) -> 0 | S24: =P24-Q24 -> 0 | X24: =U24-V24 -> 0 | AD24: =AA24-AB24 -> 0 | AH24: =AE24-AF24 -> 0 | AN24: =AK24-AL24 -> 0 | AS24: =AP24-AQ24 -> 0 | AX24: =AU24-AV24 -> 0 | BC24: =AZ24-BA24 -> 0 | BI24: =BF24-BG24 -> 0 | BN24: =BK24-BL24 -> 0 | BS24: =BP24-BQ24 -> 0 | BX24: =BU24-BV24 -> 0 | CD24: =CA24-CB24 -> 0 | CI24: =CF24-CG24 -> 0 | CN24: =CK24-CL24 -> 0 | CS24: =CP24-CQ24 -> 0
A25: 16 | B25: 総限界利益 | C25: 総利益合計 | D25: 新車 | E25: 新車台数 | J25: =SUM(P25,U25,Z25,AK25,AP25,AU25,BF25,BK25,BP25,CA25,CF25,CK25) -> 0 | K25: =SUM(Q25,V25,AA25,AL25,AQ25,AV25,BG25,BL25,BQ25,CB25,CG25,CL25) -> 0 | L25: =SUM(R25,W25,AB25,AM25,AR25,AW25,BH25,BM25,BR25,CC25,CH25,CM25) -> 0 | M25: =SUM(S25,X25,AC25,AN25,AS25,AX25,BI25,BN25,BS25,CD25,CI25,CN25) -> 0 | N25: =SUM(T25,Y25,AD25,AO25,AT25,AY25,BJ25,BO25,BT25,CE25,CJ25,CO25) -> 0 | S25: =P25-Q25 -> 0 | X25: =U25-V25 -> 0 | AD25: =AA25-AB25 -> 0 | AH25: =AE25-AF25 -> 0 | AN25: =AK25-AL25 -> 0 | AS25: =AP25-AQ25 -> 0 | AX25: =AU25-AV25 -> 0 | BC25: =AZ25-BA25 -> 0 | BI25: =BF25-BG25 -> 0 | BN25: =BK25-BL25 -> 0 | BS25: =BP25-BQ25 -> 0 | BX25: =BU25-BV25 -> 0 | CD25: =CA25-CB25 -> 0 | CI25: =CF25-CG25 -> 0 | CN25: =CK25-CL25 -> 0 | CS25: =CP25-CQ25 -> 0
A26: 17 | E26: 売上金額（架装売上含む） | J26: =SUM(P26,U26,Z26,AK26,AP26,AU26,BF26,BK26,BP26,CA26,CF26,CK26) -> 0 | K26: =SUM(Q26,V26,AA26,AL26,AQ26,AV26,BG26,BL26,BQ26,CB26,CG26,CL26) -> 0 | L26: =SUM(R26,W26,AB26,AM26,AR26,AW26,BH26,BM26,BR26,CC26,CH26,CM26) -> 0 | M26: =SUM(S26,X26,AC26,AN26,AS26,AX26,BI26,BN26,BS26,CD26,CI26,CN26) -> 0 | N26: =SUM(T26,Y26,AD26,AO26,AT26,AY26,BJ26,BO26,BT26,CE26,CJ26,CO26) -> 0 | S26: =P26-Q26 -> 0 | X26: =U26-V26 -> 0 | AD26: =AA26-AB26 -> 0 | AH26: =AE26-AF26 -> 0 | AN26: =AK26-AL26 -> 0 | AS26: =AP26-AQ26 -> 0 | AX26: =AU26-AV26 -> 0 | BC26: =AZ26-BA26 -> 0 | BI26: =BF26-BG26 -> 0 | BN26: =BK26-BL26 -> 0 | BS26: =BP26-BQ26 -> 0 | BX26: =BU26-BV26 -> 0 | CD26: =CA26-CB26 -> 0 | CI26: =CF26-CG26 -> 0 | CN26: =CK26-CL26 -> 0 | CS26: =CP26-CQ26 -> 0
A27: 18 | F27: ＜内車両値引＞ | J27: =SUM(P27,U27,Z27,AK27,AP27,AU27,BF27,BK27,BP27,CA27,CF27,CK27) -> 0 | K27: =SUM(Q27,V27,AA27,AL27,AQ27,AV27,BG27,BL27,BQ27,CB27,CG27,CL27) -> 0 | L27: =SUM(R27,W27,AB27,AM27,AR27,AW27,BH27,BM27,BR27,CC27,CH27,CM27) -> 0 | M27: =SUM(S27,X27,AC27,AN27,AS27,AX27,BI27,BN27,BS27,CD27,CI27,CN27) -> 0 | N27: =SUM(T27,Y27,AD27,AO27,AT27,AY27,BJ27,BO27,BT27,CE27,CJ27,CO27) -> 0 | S27: =P27-Q27 -> 0 | X27: =U27-V27 -> 0 | AD27: =AA27-AB27 -> 0 | AH27: =AE27-AF27 -> 0 | AN27: =AK27-AL27 -> 0 | AS27: =AP27-AQ27 -> 0 | AX27: =AU27-AV27 -> 0 | BC27: =AZ27-BA27 -> 0 | BI27: =BF27-BG27 -> 0 | BN27: =BK27-BL27 -> 0 | BS27: =BP27-BQ27 -> 0 | BX27: =BU27-BV27 -> 0 | CD27: =CA27-CB27 -> 0 | CI27: =CF27-CG27 -> 0 | CN27: =CK27-CL27 -> 0 | CS27: =CP27-CQ27 -> 0
A28: 19 | F28: 車両本体利益 | J28: =SUM(P28,U28,Z28,AK28,AP28,AU28,BF28,BK28,BP28,CA28,CF28,CK28) -> 0 | K28: =SUM(Q28,V28,AA28,AL28,AQ28,AV28,BG28,BL28,BQ28,CB28,CG28,CL28) -> 0 | L28: =SUM(R28,W28,AB28,AM28,AR28,AW28,BH28,BM28,BR28,CC28,CH28,CM28) -> 0 | M28: =SUM(S28,X28,AC28,AN28,AS28,AX28,BI28,BN28,BS28,CD28,CI28,CN28) -> 0 | N28: =SUM(T28,Y28,AD28,AO28,AT28,AY28,BJ28,BO28,BT28,CE28,CJ28,CO28) -> 0 | S28: =P28-Q28 -> 0 | X28: =U28-V28 -> 0 | AD28: =AA28-AB28 -> 0 | AH28: =AE28-AF28 -> 0 | AN28: =AK28-AL28 -> 0 | AS28: =AP28-AQ28 -> 0 | AX28: =AU28-AV28 -> 0 | BC28: =AZ28-BA28 -> 0 | BI28: =BF28-BG28 -> 0 | BN28: =BK28-BL28 -> 0 | BS28: =BP28-BQ28 -> 0 | BX28: =BU28-BV28 -> 0 | CD28: =CA28-CB28 -> 0 | CI28: =CF28-CG28 -> 0 | CN28: =CK28-CL28 -> 0 | CS28: =CP28-CQ28 -> 0
A29: 20 | F29: 架装付属品利益 | J29: =SUM(P29,U29,Z29,AK29,AP29,AU29,BF29,BK29,BP29,CA29,CF29,CK29) -> 0 | K29: =SUM(Q29,V29,AA29,AL29,AQ29,AV29,BG29,BL29,BQ29,CB29,CG29,CL29) -> 0 | L29: =SUM(R29,W29,AB29,AM29,AR29,AW29,BH29,BM29,BR29,CC29,CH29,CM29) -> 0 | M29: =SUM(S29,X29,AC29,AN29,AS29,AX29,BI29,BN29,BS29,CD29,CI29,CN29) -> 0 | N29: =SUM(T29,Y29,AD29,AO29,AT29,AY29,BJ29,BO29,BT29,CE29,CJ29,CO29) -> 0 | S29: =P29-Q29 -> 0 | X29: =U29-V29 -> 0 | AD29: =AA29-AB29 -> 0 | AH29: =AE29-AF29 -> 0 | AN29: =AK29-AL29 -> 0 | AS29: =AP29-AQ29 -> 0 | AX29: =AU29-AV29 -> 0 | BC29: =AZ29-BA29 -> 0 | BI29: =BF29-BG29 -> 0 | BN29: =BK29-BL29 -> 0 | BS29: =BP29-BQ29 -> 0 | BX29: =BU29-BV29 -> 0 | CD29: =CA29-CB29 -> 0 | CI29: =CF29-CG29 -> 0 | CN29: =CK29-CL29 -> 0 | CS29: =CP29-CQ29 -> 0
A30: 21 | F30: 車両収入手数料 | J30: =SUM(P30,U30,Z30,AK30,AP30,AU30,BF30,BK30,BP30,CA30,CF30,CK30) -> 0 | K30: =SUM(Q30,V30,AA30,AL30,AQ30,AV30,BG30,BL30,BQ30,CB30,CG30,CL30) -> 0 | L30: =SUM(R30,W30,AB30,AM30,AR30,AW30,BH30,BM30,BR30,CC30,CH30,CM30) -> 0 | M30: =SUM(S30,X30,AC30,AN30,AS30,AX30,BI30,BN30,BS30,CD30,CI30,CN30) -> 0 | N30: =SUM(T30,Y30,AD30,AO30,AT30,AY30,BJ30,BO30,BT30,CE30,CJ30,CO30) -> 0 | S30: =P30-Q30 -> 0 | X30: =U30-V30 -> 0 | AD30: =AA30-AB30 -> 0 | AH30: =AE30-AF30 -> 0 | AN30: =AK30-AL30 -> 0 | AS30: =AP30-AQ30 -> 0 | AX30: =AU30-AV30 -> 0 | BC30: =AZ30-BA30 -> 0 | BI30: =BF30-BG30 -> 0 | BN30: =BK30-BL30 -> 0 | BS30: =BP30-BQ30 -> 0 | BX30: =BU30-BV30 -> 0 | CD30: =CA30-CB30 -> 0 | CI30: =CF30-CG30 -> 0 | CN30: =CK30-CL30 -> 0 | CS30: =CP30-CQ30 -> 0
A31: 22 | F31: 登録収入手数料 | J31: =SUM(P31,U31,Z31,AK31,AP31,AU31,BF31,BK31,BP31,CA31,CF31,CK31) -> 0 | K31: =SUM(Q31,V31,AA31,AL31,AQ31,AV31,BG31,BL31,BQ31,CB31,CG31,CL31) -> 0 | L31: =SUM(R31,W31,AB31,AM31,AR31,AW31,BH31,BM31,BR31,CC31,CH31,CM31) -> 0 | M31: =SUM(S31,X31,AC31,AN31,AS31,AX31,BI31,BN31,BS31,CD31,CI31,CN31) -> 0 | N31: =SUM(T31,Y31,AD31,AO31,AT31,AY31,BJ31,BO31,BT31,CE31,CJ31,CO31) -> 0 | S31: =P31-Q31 -> 0 | X31: =U31-V31 -> 0 | AD31: =AA31-AB31 -> 0 | AH31: =AE31-AF31 -> 0 | AN31: =AK31-AL31 -> 0 | AS31: =AP31-AQ31 -> 0 | AX31: =AU31-AV31 -> 0 | BC31: =AZ31-BA31 -> 0 | BI31: =BF31-BG31 -> 0 | BN31: =BK31-BL31 -> 0 | BS31: =BP31-BQ31 -> 0 | BX31: =BU31-BV31 -> 0 | CD31: =CA31-CB31 -> 0 | CI31: =CF31-CG31 -> 0 | CN31: =CK31-CL31 -> 0 | CS31: =CP31-CQ31 -> 0
A32: 23 | F32: クレジット利益 | J32: =SUM(P32,U32,Z32,AK32,AP32,AU32,BF32,BK32,BP32,CA32,CF32,CK32) -> 0 | K32: =SUM(Q32,V32,AA32,AL32,AQ32,AV32,BG32,BL32,BQ32,CB32,CG32,CL32) -> 0 | L32: =SUM(R32,W32,AB32,AM32,AR32,AW32,BH32,BM32,BR32,CC32,CH32,CM32) -> 0 | M32: =SUM(S32,X32,AC32,AN32,AS32,AX32,BI32,BN32,BS32,CD32,CI32,CN32) -> 0 | N32: =SUM(T32,Y32,AD32,AO32,AT32,AY32,BJ32,BO32,BT32,CE32,CJ32,CO32) -> 0 | S32: =P32-Q32 -> 0 | X32: =U32-V32 -> 0 | AD32: =AA32-AB32 -> 0 | AH32: =AE32-AF32 -> 0 | AN32: =AK32-AL32 -> 0 | AS32: =AP32-AQ32 -> 0 | AX32: =AU32-AV32 -> 0 | BC32: =AZ32-BA32 -> 0 | BI32: =BF32-BG32 -> 0 | BN32: =BK32-BL32 -> 0 | BS32: =BP32-BQ32 -> 0 | BX32: =BU32-BV32 -> 0 | CD32: =CA32-CB32 -> 0 | CI32: =CF32-CG32 -> 0 | CN32: =CK32-CL32 -> 0 | CS32: =CP32-CQ32 -> 0
A33: 24 | F33: 販売手数料 | J33: =SUM(P33,U33,Z33,AK33,AP33,AU33,BF33,BK33,BP33,CA33,CF33,CK33) -> 0 | K33: =SUM(Q33,V33,AA33,AL33,AQ33,AV33,BG33,BL33,BQ33,CB33,CG33,CL33) -> 0 | L33: =SUM(R33,W33,AB33,AM33,AR33,AW33,BH33,BM33,BR33,CC33,CH33,CM33) -> 0 | M33: =SUM(S33,X33,AC33,AN33,AS33,AX33,BI33,BN33,BS33,CD33,CI33,CN33) -> 0 | N33: =SUM(T33,Y33,AD33,AO33,AT33,AY33,BJ33,BO33,BT33,CE33,CJ33,CO33) -> 0 | S33: =P33-Q33 -> 0 | X33: =U33-V33 -> 0 | AD33: =AA33-AB33 -> 0 | AH33: =AE33-AF33 -> 0 | AN33: =AK33-AL33 -> 0 | AS33: =AP33-AQ33 -> 0 | AX33: =AU33-AV33 -> 0 | BC33: =AZ33-BA33 -> 0 | BI33: =BF33-BG33 -> 0 | BN33: =BK33-BL33 -> 0 | BS33: =BP33-BQ33 -> 0 | BX33: =BU33-BV33 -> 0 | CD33: =CA33-CB33 -> 0 | CI33: =CF33-CG33 -> 0 | CN33: =CK33-CL33 -> 0 | CS33: =CP33-CQ33 -> 0
A34: 25 | E34: 新車総粗利 | J34: =SUM(P34,U34,Z34,AK34,AP34,AU34,BF34,BK34,BP34,CA34,CF34,CK34) -> 0 | K34: =SUM(Q34,V34,AA34,AL34,AQ34,AV34,BG34,BL34,BQ34,CB34,CG34,CL34) -> 0 | L34: =SUM(R34,W34,AB34,AM34,AR34,AW34,BH34,BM34,BR34,CC34,CH34,CM34) -> 0 | M34: =SUM(S34,X34,AC34,AN34,AS34,AX34,BI34,BN34,BS34,CD34,CI34,CN34) -> 0 | N34: =SUM(T34,Y34,AD34,AO34,AT34,AY34,BJ34,BO34,BT34,CE34,CJ34,CO34) -> 0 | S34: =P34-Q34 -> 0 | X34: =U34-V34 -> 0 | AD34: =AA34-AB34 -> 0 | AH34: =AE34-AF34 -> 0 | AN34: =AK34-AL34 -> 0 | AS34: =AP34-AQ34 -> 0 | AX34: =AU34-AV34 -> 0 | BC34: =AZ34-BA34 -> 0 | BI34: =BF34-BG34 -> 0 | BN34: =BK34-BL34 -> 0 | BS34: =BP34-BQ34 -> 0 | BX34: =BU34-BV34 -> 0 | CD34: =CA34-CB34 -> 0 | CI34: =CF34-CG34 -> 0 | CN34: =CK34-CL34 -> 0 | CS34: =CP34-CQ34 -> 0
A35: 26 | E35: 販売費 | F35: 販手・サービス・雑費 | J35: =SUM(P35,U35,Z35,AK35,AP35,AU35,BF35,BK35,BP35,CA35,CF35,CK35) -> 0 | K35: =SUM(Q35,V35,AA35,AL35,AQ35,AV35,BG35,BL35,BQ35,CB35,CG35,CL35) -> 0 | L35: =SUM(R35,W35,AB35,AM35,AR35,AW35,BH35,BM35,BR35,CC35,CH35,CM35) -> 0 | M35: =SUM(S35,X35,AC35,AN35,AS35,AX35,BI35,BN35,BS35,CD35,CI35,CN35) -> 0 | N35: =SUM(T35,Y35,AD35,AO35,AT35,AY35,BJ35,BO35,BT35,CE35,CJ35,CO35) -> 0 | S35: =P35-Q35 -> 0 | X35: =U35-V35 -> 0 | AD35: =AA35-AB35 -> 0 | AH35: =AE35-AF35 -> 0 | AN35: =AK35-AL35 -> 0 | AS35: =AP35-AQ35 -> 0 | AX35: =AU35-AV35 -> 0 | BC35: =AZ35-BA35 -> 0 | BI35: =BF35-BG35 -> 0 | BN35: =BK35-BL35 -> 0 | BS35: =BP35-BQ35 -> 0 | BX35: =BU35-BV35 -> 0 | CD35: =CA35-CB35 -> 0 | CI35: =CF35-CG35 -> 0 | CN35: =CK35-CL35 -> 0 | CS35: =CP35-CQ35 -> 0
A36: 27 | F36: 納車費・運送保管費 | J36: =SUM(P36,U36,Z36,AK36,AP36,AU36,BF36,BK36,BP36,CA36,CF36,CK36) -> 0 | K36: =SUM(Q36,V36,AA36,AL36,AQ36,AV36,BG36,BL36,BQ36,CB36,CG36,CL36) -> 0 | L36: =SUM(R36,W36,AB36,AM36,AR36,AW36,BH36,BM36,BR36,CC36,CH36,CM36) -> 0 | M36: =SUM(S36,X36,AC36,AN36,AS36,AX36,BI36,BN36,BS36,CD36,CI36,CN36) -> 0 | N36: =SUM(T36,Y36,AD36,AO36,AT36,AY36,BJ36,BO36,BT36,CE36,CJ36,CO36) -> 0 | S36: =P36-Q36 -> 0 | X36: =U36-V36 -> 0 | AD36: =AA36-AB36 -> 0 | AH36: =AE36-AF36 -> 0 | AN36: =AK36-AL36 -> 0 | AS36: =AP36-AQ36 -> 0 | AX36: =AU36-AV36 -> 0 | BC36: =AZ36-BA36 -> 0 | BI36: =BF36-BG36 -> 0 | BN36: =BK36-BL36 -> 0 | BS36: =BP36-BQ36 -> 0 | BX36: =BU36-BV36 -> 0 | CD36: =CA36-CB36 -> 0 | CI36: =CF36-CG36 -> 0 | CN36: =CK36-CL36 -> 0 | CS36: =CP36-CQ36 -> 0
A37: 28 | F37: 広告宣伝費 | J37: =SUM(P37,U37,Z37,AK37,AP37,AU37,BF37,BK37,BP37,CA37,CF37,CK37) -> 0 | K37: =SUM(Q37,V37,AA37,AL37,AQ37,AV37,BG37,BL37,BQ37,CB37,CG37,CL37) -> 0 | L37: =SUM(R37,W37,AB37,AM37,AR37,AW37,BH37,BM37,BR37,CC37,CH37,CM37) -> 0 | M37: =SUM(S37,X37,AC37,AN37,AS37,AX37,BI37,BN37,BS37,CD37,CI37,CN37) -> 0 | N37: =SUM(T37,Y37,AD37,AO37,AT37,AY37,BJ37,BO37,BT37,CE37,CJ37,CO37) -> 0 | S37: =P37-Q37 -> 0 | X37: =U37-V37 -> 0 | AD37: =AA37-AB37 -> 0 | AH37: =AE37-AF37 -> 0 | AN37: =AK37-AL37 -> 0 | AS37: =AP37-AQ37 -> 0 | AX37: =AU37-AV37 -> 0 | BC37: =AZ37-BA37 -> 0 | BI37: =BF37-BG37 -> 0 | BN37: =BK37-BL37 -> 0 | BS37: =BP37-BQ37 -> 0 | BX37: =BU37-BV37 -> 0 | CD37: =CA37-CB37 -> 0 | CI37: =CF37-CG37 -> 0 | CN37: =CK37-CL37 -> 0 | CS37: =CP37-CQ37 -> 0
A38: 29 | F38: デモカー・代車費 | J38: =SUM(P38,U38,Z38,AK38,AP38,AU38,BF38,BK38,BP38,CA38,CF38,CK38) -> 0 | K38: =SUM(Q38,V38,AA38,AL38,AQ38,AV38,BG38,BL38,BQ38,CB38,CG38,CL38) -> 0 | L38: =SUM(R38,W38,AB38,AM38,AR38,AW38,BH38,BM38,BR38,CC38,CH38,CM38) -> 0 | M38: =SUM(S38,X38,AC38,AN38,AS38,AX38,BI38,BN38,BS38,CD38,CI38,CN38) -> 0 | N38: =SUM(T38,Y38,AD38,AO38,AT38,AY38,BJ38,BO38,BT38,CE38,CJ38,CO38) -> 0 | S38: =P38-Q38 -> 0 | X38: =U38-V38 -> 0 | AD38: =AA38-AB38 -> 0 | AH38: =AE38-AF38 -> 0 | AN38: =AK38-AL38 -> 0 | AS38: =AP38-AQ38 -> 0 | AX38: =AU38-AV38 -> 0 | BC38: =AZ38-BA38 -> 0 | BI38: =BF38-BG38 -> 0 | BN38: =BK38-BL38 -> 0 | BS38: =BP38-BQ38 -> 0 | BX38: =BU38-BV38 -> 0 | CD38: =CA38-CB38 -> 0 | CI38: =CF38-CG38 -> 0 | CN38: =CK38-CL38 -> 0 | CS38: =CP38-CQ38 -> 0
A39: 30 | F39: 本部負担金 | J39: =SUM(P39,U39,Z39,AK39,AP39,AU39,BF39,BK39,BP39,CA39,CF39,CK39) -> 0 | K39: =SUM(Q39,V39,AA39,AL39,AQ39,AV39,BG39,BL39,BQ39,CB39,CG39,CL39) -> 0 | L39: =SUM(R39,W39,AB39,AM39,AR39,AW39,BH39,BM39,BR39,CC39,CH39,CM39) -> 0 | M39: =SUM(S39,X39,AC39,AN39,AS39,AX39,BI39,BN39,BS39,CD39,CI39,CN39) -> 0 | N39: =SUM(T39,Y39,AD39,AO39,AT39,AY39,BJ39,BO39,BT39,CE39,CJ39,CO39) -> 0 | S39: =P39-Q39 -> 0 | X39: =U39-V39 -> 0 | AD39: =AA39-AB39 -> 0 | AH39: =AE39-AF39 -> 0 | AN39: =AK39-AL39 -> 0 | AS39: =AP39-AQ39 -> 0 | AX39: =AU39-AV39 -> 0 | BC39: =AZ39-BA39 -> 0 | BI39: =BF39-BG39 -> 0 | BN39: =BK39-BL39 -> 0 | BS39: =BP39-BQ39 -> 0 | BX39: =BU39-BV39 -> 0 | CD39: =CA39-CB39 -> 0 | CI39: =CF39-CG39 -> 0 | CN39: =CK39-CL39 -> 0 | CS39: =CP39-CQ39 -> 0
A40: 31 | F40: 小計 | J40: =SUM(P40,U40,Z40,AK40,AP40,AU40,BF40,BK40,BP40,CA40,CF40,CK40) -> 0 | K40: =SUM(Q40,V40,AA40,AL40,AQ40,AV40,BG40,BL40,BQ40,CB40,CG40,CL40) -> 0 | L40: =SUM(R40,W40,AB40,AM40,AR40,AW40,BH40,BM40,BR40,CC40,CH40,CM40) -> 0 | M40: =SUM(S40,X40,AC40,AN40,AS40,AX40,BI40,BN40,BS40,CD40,CI40,CN40) -> 0 | N40: =SUM(T40,Y40,AD40,AO40,AT40,AY40,BJ40,BO40,BT40,CE40,CJ40,CO40) -> 0 | S40: =P40-Q40 -> 0 | X40: =U40-V40 -> 0 | AD40: =AA40-AB40 -> 0 | AH40: =AE40-AF40 -> 0 | AN40: =AK40-AL40 -> 0 | AS40: =AP40-AQ40 -> 0 | AX40: =AU40-AV40 -> 0 | BC40: =AZ40-BA40 -> 0 | BI40: =BF40-BG40 -> 0 | BN40: =BK40-BL40 -> 0 | BS40: =BP40-BQ40 -> 0 | BX40: =BU40-BV40 -> 0 | CD40: =CA40-CB40 -> 0 | CI40: =CF40-CG40 -> 0 | CN40: =CK40-CL40 -> 0 | CS40: =CP40-CQ40 -> 0
A41: 32 | E41: 新車限界利益 | J41: =SUM(P41,U41,Z41,AK41,AP41,AU41,BF41,BK41,BP41,CA41,CF41,CK41) -> 0 | K41: =SUM(Q41,V41,AA41,AL41,AQ41,AV41,BG41,BL41,BQ41,CB41,CG41,CL41) -> 0 | L41: =SUM(R41,W41,AB41,AM41,AR41,AW41,BH41,BM41,BR41,CC41,CH41,CM41) -> 0 | M41: =SUM(S41,X41,AC41,AN41,AS41,AX41,BI41,BN41,BS41,CD41,CI41,CN41) -> 0 | N41: =SUM(T41,Y41,AD41,AO41,AT41,AY41,BJ41,BO41,BT41,CE41,CJ41,CO41) -> 0 | S41: =P41-Q41 -> 0 | X41: =U41-V41 -> 0 | AD41: =AA41-AB41 -> 0 | AH41: =AE41-AF41 -> 0 | AN41: =AK41-AL41 -> 0 | AS41: =AP41-AQ41 -> 0 | AX41: =AU41-AV41 -> 0 | BC41: =AZ41-BA41 -> 0 | BI41: =BF41-BG41 -> 0 | BN41: =BK41-BL41 -> 0 | BS41: =BP41-BQ41 -> 0 | BX41: =BU41-BV41 -> 0 | CD41: =CA41-CB41 -> 0 | CI41: =CF41-CG41 -> 0 | CN41: =CK41-CL41 -> 0 | CS41: =CP41-CQ41 -> 0
A42: 33 | D42: 中古車 | E42: 直売 | F42: 直売台数 | J42: =SUM(P42,U42,Z42,AK42,AP42,AU42,BF42,BK42,BP42,CA42,CF42,CK42) -> 0 | K42: =SUM(Q42,V42,AA42,AL42,AQ42,AV42,BG42,BL42,BQ42,CB42,CG42,CL42) -> 0 | L42: =SUM(R42,W42,AB42,AM42,AR42,AW42,BH42,BM42,BR42,CC42,CH42,CM42) -> 0 | M42: =SUM(S42,X42,AC42,AN42,AS42,AX42,BI42,BN42,BS42,CD42,CI42,CN42) -> 0 | N42: =SUM(T42,Y42,AD42,AO42,AT42,AY42,BJ42,BO42,BT42,CE42,CJ42,CO42) -> 0 | S42: =P42-Q42 -> 0 | X42: =U42-V42 -> 0 | AD42: =AA42-AB42 -> 0 | AH42: =AE42-AF42 -> 0 | AN42: =AK42-AL42 -> 0 | AS42: =AP42-AQ42 -> 0 | AX42: =AU42-AV42 -> 0 | BC42: =AZ42-BA42 -> 0 | BI42: =BF42-BG42 -> 0 | BN42: =BK42-BL42 -> 0 | BS42: =BP42-BQ42 -> 0 | BX42: =BU42-BV42 -> 0 | CD42: =CA42-CB42 -> 0 | CI42: =CF42-CG42 -> 0 | CN42: =CK42-CL42 -> 0 | CS42: =CP42-CQ42 -> 0
A43: 34 | F43: 売上金額 | J43: =SUM(P43,U43,Z43,AK43,AP43,AU43,BF43,BK43,BP43,CA43,CF43,CK43) -> 0 | K43: =SUM(Q43,V43,AA43,AL43,AQ43,AV43,BG43,BL43,BQ43,CB43,CG43,CL43) -> 0 | L43: =SUM(R43,W43,AB43,AM43,AR43,AW43,BH43,BM43,BR43,CC43,CH43,CM43) -> 0 | M43: =SUM(S43,X43,AC43,AN43,AS43,AX43,BI43,BN43,BS43,CD43,CI43,CN43) -> 0 | N43: =SUM(T43,Y43,AD43,AO43,AT43,AY43,BJ43,BO43,BT43,CE43,CJ43,CO43) -> 0 | S43: =P43-Q43 -> 0 | X43: =U43-V43 -> 0 | AD43: =AA43-AB43 -> 0 | AH43: =AE43-AF43 -> 0 | AN43: =AK43-AL43 -> 0 | AS43: =AP43-AQ43 -> 0 | AX43: =AU43-AV43 -> 0 | BC43: =AZ43-BA43 -> 0 | BI43: =BF43-BG43 -> 0 | BN43: =BK43-BL43 -> 0 | BS43: =BP43-BQ43 -> 0 | BX43: =BU43-BV43 -> 0 | CD43: =CA43-CB43 -> 0 | CI43: =CF43-CG43 -> 0 | CN43: =CK43-CL43 -> 0 | CS43: =CP43-CQ43 -> 0
...

Sheet 販売２
B1: 予算表
B3: 期：
B5: 部署：
B7: 項目 | J7: 年間計 | P7: １０月 | U7: １１月 | Z7: １２月 | AE7: １０月～１２月合計 | AK7: １月 | AP7: ２月 | AU7: ３月 | AZ7: １月～３月合計 | BF7: ４月 | BK7: ５月 | BP7: ６月 | BU7: ４月～６月合計 | CA7: ７月 | CF7: ８月 | CK7: ９月 | CP7: ７月～９月合計
A8: LineNo
J9: 計画 | K9: 前年実績 | L9: 指標 | M9: 差 | N9: 前年比 | P9: 計画 | Q9: 前年実績 | R9: 指標 | S9: 差 | T9: 前年比 | U9: 計画 | V9: 前年実績 | W9: 指標 | X9: 差 | Y9: 前年比 | Z9: 計画 | AA9: 前年実績 | AB9: 指標 | AC9: 差 | AD9: 前年比 | AE9: 計画 | AF9: 前年実績 | AG9: 指標 | AH9: 差 | AI9: 前年比 | AK9: 計画 | AL9: 前年実績 | AM9: 指標 | AN9: 差 | AO9: 前年比 | AP9: 計画 | AQ9: 前年実績 | AR9: 指標 | AS9: 差 | AT9: 前年比 | AU9: 計画 | AV9: 前年実績 | AW9: 指標 | AX9: 差 | AY9: 前年比 | AZ9: 計画 | BA9: 前年実績 | BB9: 指標 | BC9: 差 | BD9: 前年比 | BF9: 計画 | BG9: 前年実績 | BH9: 指標 | BI9: 差 | BJ9: 前年比 | BK9: 計画 | BL9: 前年実績 | BM9: 指標 | BN9: 差 | BO9: 前年比 | BP9: 計画 | BQ9: 前年実績 | BR9: 指標 | BS9: 差 | BT9: 前年比 | BU9: 計画 | BV9: 前年実績 | BW9: 指標 | BX9: 差 | BY9: 前年比 | CA9: 計画 | CB9: 前年実績 | CC9: 指標 | CD9: 差 | CE9: 前年比 | CF9: 計画 | CG9: 前年実績 | CH9: 指標 | CI9: 差 | CJ9: 前年比 | CK9: 計画 | CL9: 前年実績 | CM9: 指標 | CN9: 差 | CO9: 前年比 | CP9: 計画 | CQ9: 前年実績 | CR9: 指標 | CS9: 差 | CT9: 前年比
A10: 1 | B10: 営業スタッフ数 | J10: =SUM(P10,U10,Z10,AK10,AP10,AU10,BF10,BK10,BP10,CA10,CF10,CK10) -> 0 | K10: =SUM(Q10,V10,AA10,AL10,AQ10,AV10,BG10,BL10,BQ10,CB10,CG10,CL10) -> 0 | L10: =SUM(R10,W10,AB10,AM10,AR10,AW10,BH10,BM10,BR10,CC10,CH10,CM10) -> 0 | M10: =SUM(S10,X10,AC10,AN10,AS10,AX10,BI10,BN10,BS10,CD10,CI10,CN10) -> 0 | N10: =SUM(T10,Y10,AD10,AO10,AT10,AY10,BJ10,BO10,BT10,CE10,CJ10,CO10) -> 0 | S10: =P10-Q10 -> 0 | X10: =U10-V10 -> 0 | AD10: =AA10-AB10 -> 0 | AH10: =AE10-AF10 -> 0 | AN10: =AK10-AL10 -> 0 | AS10: =AP10-AQ10 -> 0 | AX10: =AU10-AV10 -> 0 | BC10: =AZ10-BA10 -> 0 | BI10: =BF10-BG10 -> 0 | BN10: =BK10-BL10 -> 0 | BS10: =BP10-BQ10 -> 0 | BX10: =BU10-BV10 -> 0 | CD10: =CA10-CB10 -> 0 | CI10: =CF10-CG10 -> 0 | CN10: =CK10-CL10 -> 0 | CS10: =CP10-CQ10 -> 0
A11: 2 | B11: 自新直顧客数 | J11: =SUM(P11,U11,Z11,AK11,AP11,AU11,BF11,BK11,BP11,CA11,CF11,CK11) -> 0 | K11: =SUM(Q11,V11,AA11,AL11,AQ11,AV11,BG11,BL11,BQ11,CB11,CG11,CL11) -> 0 | L11: =SUM(R11,W11,AB11,AM11,AR11,AW11,BH11,BM11,BR11,CC11,CH11,CM11) -> 0 | M11: =SUM(S11,X11,AC11,AN11,AS11,AX11,BI11,BN11,BS11,CD11,CI11,CN11) -> 0 | N11: =SUM(T11,Y11,AD11,AO11,AT11,AY11,BJ11,BO11,BT11,CE11,CJ11,CO11) -> 0 | S11: =P11-Q11 -> 0 | X11: =U11-V11 -> 0 | AD11: =AA11-AB11 -> 0 | AH11: =AE11-AF11 -> 0 | AN11: =AK11-AL11 -> 0 | AS11: =AP11-AQ11 -> 0 | AX11: =AU11-AV11 -> 0 | BC11: =AZ11-BA11 -> 0 | BI11: =BF11-BG11 -> 0 | BN11: =BK11-BL11 -> 0 | BS11: =BP11-BQ11 -> 0 | BX11: =BU11-BV11 -> 0 | CD11: =CA11-CB11 -> 0 | CI11: =CF11-CG11 -> 0 | CN11: =CK11-CL11 -> 0 | CS11: =CP11-CQ11 -> 0
A12: 3 | B12: 顧客代替台数 | J12: =SUM(P12,U12,Z12,AK12,AP12,AU12,BF12,BK12,BP12,CA12,CF12,CK12) -> 0 | K12: =SUM(Q12,V12,AA12,AL12,AQ12,AV12,BG12,BL12,BQ12,CB12,CG12,CL12) -> 0 | L12: =SUM(R12,W12,AB12,AM12,AR12,AW12,BH12,BM12,BR12,CC12,CH12,CM12) -> 0 | M12: =SUM(S12,X12,AC12,AN12,AS12,AX12,BI12,BN12,BS12,CD12,CI12,CN12) -> 0 | N12: =SUM(T12,Y12,AD12,AO12,AT12,AY12,BJ12,BO12,BT12,CE12,CJ12,CO12) -> 0 | S12: =P12-Q12 -> 0 | X12: =U12-V12 -> 0 | AD12: =AA12-AB12 -> 0 | AH12: =AE12-AF12 -> 0 | AN12: =AK12-AL12 -> 0 | AS12: =AP12-AQ12 -> 0 | AX12: =AU12-AV12 -> 0 | BC12: =AZ12-BA12 -> 0 | BI12: =BF12-BG12 -> 0 | BN12: =BK12-BL12 -> 0 | BS12: =BP12-BQ12 -> 0 | BX12: =BU12-BV12 -> 0 | CD12: =CA12-CB12 -> 0 | CI12: =CF12-CG12 -> 0 | CN12: =CK12-CL12 -> 0 | CS12: =CP12-CQ12 -> 0
A13: 4 | B13: 自中直顧客数 | J13: =SUM(P13,U13,Z13,AK13,AP13,AU13,BF13,BK13,BP13,CA13,CF13,CK13) -> 0 | K13: =SUM(Q13,V13,AA13,AL13,AQ13,AV13,BG13,BL13,BQ13,CB13,CG13,CL13) -> 0 | L13: =SUM(R13,W13,AB13,AM13,AR13,AW13,BH13,BM13,BR13,CC13,CH13,CM13) -> 0 | M13: =SUM(S13,X13,AC13,AN13,AS13,AX13,BI13,BN13,BS13,CD13,CI13,CN13) -> 0 | N13: =SUM(T13,Y13,AD13,AO13,AT13,AY13,BJ13,BO13,BT13,CE13,CJ13,CO13) -> 0 | S13: =P13-Q13 -> 0 | X13: =U13-V13 -> 0 | AD13: =AA13-AB13 -> 0 | AH13: =AE13-AF13 -> 0 | AN13: =AK13-AL13 -> 0 | AS13: =AP13-AQ13 -> 0 | AX13: =AU13-AV13 -> 0 | BC13: =AZ13-BA13 -> 0 | BI13: =BF13-BG13 -> 0 | BN13: =BK13-BL13 -> 0 | BS13: =BP13-BQ13 -> 0 | BX13: =BU13-BV13 -> 0 | CD13: =CA13-CB13 -> 0 | CI13: =CF13-CG13 -> 0 | CN13: =CK13-CL13 -> 0 | CS13: =CP13-CQ13 -> 0
A14: 5 | B14: サービス直人員 | J14: =SUM(P14,U14,Z14,AK14,AP14,AU14,BF14,BK14,BP14,CA14,CF14,CK14) -> 0 | K14: =SUM(Q14,V14,AA14,AL14,AQ14,AV14,BG14,BL14,BQ14,CB14,CG14,CL14) -> 0 | L14: =SUM(R14,W14,AB14,AM14,AR14,AW14,BH14,BM14,BR14,CC14,CH14,CM14) -> 0 | M14: =SUM(S14,X14,AC14,AN14,AS14,AX14,BI14,BN14,BS14,CD14,CI14,CN14) -> 0 | N14: =SUM(T14,Y14,AD14,AO14,AT14,AY14,BJ14,BO14,BT14,CE14,CJ14,CO14) -> 0 | S14: =P14-Q14 -> 0 | X14: =U14-V14 -> 0 | AD14: =AA14-AB14 -> 0 | AH14: =AE14-AF14 -> 0 | AN14: =AK14-AL14 -> 0 | AS14: =AP14-AQ14 -> 0 | AX14: =AU14-AV14 -> 0 | BC14: =AZ14-BA14 -> 0 | BI14: =BF14-BG14 -> 0 | BN14: =BK14-BL14 -> 0 | BS14: =BP14-BQ14 -> 0 | BX14: =BU14-BV14 -> 0 | CD14: =CA14-CB14 -> 0 | CI14: =CF14-CG14 -> 0 | CN14: =CK14-CL14 -> 0 | CS14: =CP14-CQ14 -> 0
A15: 6 | B15: サービス管理顧客数 | J15: =SUM(P15,U15,Z15,AK15,AP15,AU15,BF15,BK15,BP15,CA15,CF15,CK15) -> 0 | K15: =SUM(Q15,V15,AA15,AL15,AQ15,AV15,BG15,BL15,BQ15,CB15,CG15,CL15) -> 0 | L15: =SUM(R15,W15,AB15,AM15,AR15,AW15,BH15,BM15,BR15,CC15,CH15,CM15) -> 0 | M15: =SUM(S15,X15,AC15,AN15,AS15,AX15,BI15,BN15,BS15,CD15,CI15,CN15) -> 0 | N15: =SUM(T15,Y15,AD15,AO15,AT15,AY15,BJ15,BO15,BT15,CE15,CJ15,CO15) -> 0 | S15: =P15-Q15 -> 0 | X15: =U15-V15 -> 0 | AD15: =AA15-AB15 -> 0 | AH15: =AE15-AF15 -> 0 | AN15: =AK15-AL15 -> 0 | AS15: =AP15-AQ15 -> 0 | AX15: =AU15-AV15 -> 0 | BC15: =AZ15-BA15 -> 0 | BI15: =BF15-BG15 -> 0 | BN15: =BK15-BL15 -> 0 | BS15: =BP15-BQ15 -> 0 | BX15: =BU15-BV15 -> 0 | CD15: =CA15-CB15 -> 0 | CI15: =CF15-CG15 -> 0 | CN15: =CK15-CL15 -> 0 | CS15: =CP15-CQ15 -> 0
A16: 7 | B16: 車検対象台数 | J16: =SUM(P16,U16,Z16,AK16,AP16,AU16,BF16,BK16,BP16,CA16,CF16,CK16) -> 0 | K16: =SUM(Q16,V16,AA16,AL16,AQ16,AV16,BG16,BL16,BQ16,CB16,CG16,CL16) -> 0 | L16: =SUM(R16,W16,AB16,AM16,AR16,AW16,BH16,BM16,BR16,CC16,CH16,CM16) -> 0 | M16: =SUM(S16,X16,AC16,AN16,AS16,AX16,BI16,BN16,BS16,CD16,CI16,CN16) -> 0 | N16: =SUM(T16,Y16,AD16,AO16,AT16,AY16,BJ16,BO16,BT16,CE16,CJ16,CO16) -> 0 | S16: =P16-Q16 -> 0 | X16: =U16-V16 -> 0 | AD16: =AA16-AB16 -> 0 | AH16: =AE16-AF16 -> 0 | AN16: =AK16-AL16 -> 0 | AS16: =AP16-AQ16 -> 0 | AX16: =AU16-AV16 -> 0 | BC16: =AZ16-BA16 -> 0 | BI16: =BF16-BG16 -> 0 | BN16: =BK16-BL16 -> 0 | BS16: =BP16-BQ16 -> 0 | BX16: =BU16-BV16 -> 0 | CD16: =CA16-CB16 -> 0 | CI16: =CF16-CG16 -> 0 | CN16: =CK16-CL16 -> 0 | CS16: =CP16-CQ16 -> 0
A17: 8 | C17: 内初回車検対象台数 | J17: =SUM(P17,U17,Z17,AK17,AP17,AU17,BF17,BK17,BP17,CA17,CF17,CK17) -> 0 | K17: =SUM(Q17,V17,AA17,AL17,AQ17,AV17,BG17,BL17,BQ17,CB17,CG17,CL17) -> 0 | L17: =SUM(R17,W17,AB17,AM17,AR17,AW17,BH17,BM17,BR17,CC17,CH17,CM17) -> 0 | M17: =SUM(S17,X17,AC17,AN17,AS17,AX17,BI17,BN17,BS17,CD17,CI17,CN17) -> 0 | N17: =SUM(T17,Y17,AD17,AO17,AT17,AY17,BJ17,BO17,BT17,CE17,CJ17,CO17) -> 0 | S17: =P17-Q17 -> 0 | X17: =U17-V17 -> 0 | AD17: =AA17-AB17 -> 0 | AH17: =AE17-AF17 -> 0 | AN17: =AK17-AL17 -> 0 | AS17: =AP17-AQ17 -> 0 | AX17: =AU17-AV17 -> 0 | BC17: =AZ17-BA17 -> 0 | BI17: =BF17-BG17 -> 0 | BN17: =BK17-BL17 -> 0 | BS17: =BP17-BQ17 -> 0 | BX17: =BU17-BV17 -> 0 | CD17: =CA17-CB17 -> 0 | CI17: =CF17-CG17 -> 0 | CN17: =CK17-CL17 -> 0 | CS17: =CP17-CQ17 -> 0
A18: 9 | B18: 初回車検入庫 | J18: =SUM(P18,U18,Z18,AK18,AP18,AU18,BF18,BK18,BP18,CA18,CF18,CK18) -> 0 | K18: =SUM(Q18,V18,AA18,AL18,AQ18,AV18,BG18,BL18,BQ18,CB18,CG18,CL18) -> 0 | L18: =SUM(R18,W18,AB18,AM18,AR18,AW18,BH18,BM18,BR18,CC18,CH18,CM18) -> 0 | M18: =SUM(S18,X18,AC18,AN18,AS18,AX18,BI18,BN18,BS18,CD18,CI18,CN18) -> 0 | N18: =SUM(T18,Y18,AD18,AO18,AT18,AY18,BJ18,BO18,BT18,CE18,CJ18,CO18) -> 0 | S18: =P18-Q18 -> 0 | X18: =U18-V18 -> 0 | AD18: =AA18-AB18 -> 0 | AH18: =AE18-AF18 -> 0 | AN18: =AK18-AL18 -> 0 | AS18: =AP18-AQ18 -> 0 | AX18: =AU18-AV18 -> 0 | BC18: =AZ18-BA18 -> 0 | BI18: =BF18-BG18 -> 0 | BN18: =BK18-BL18 -> 0 | BS18: =BP18-BQ18 -> 0 | BX18: =BU18-BV18 -> 0 | CD18: =CA18-CB18 -> 0 | CI18: =CF18-CG18 -> 0 | CN18: =CK18-CL18 -> 0 | CS18: =CP18-CQ18 -> 0
A19: 10 | B19: 有償入庫台数 | J19: =SUM(P19,U19,Z19,AK19,AP19,AU19,BF19,BK19,BP19,CA19,CF19,CK19) -> 0 | K19: =SUM(Q19,V19,AA19,AL19,AQ19,AV19,BG19,BL19,BQ19,CB19,CG19,CL19) -> 0 | L19: =SUM(R19,W19,AB19,AM19,AR19,AW19,BH19,BM19,BR19,CC19,CH19,CM19) -> 0 | M19: =SUM(S19,X19,AC19,AN19,AS19,AX19,BI19,BN19,BS19,CD19,CI19,CN19) -> 0 | N19: =SUM(T19,Y19,AD19,AO19,AT19,AY19,BJ19,BO19,BT19,CE19,CJ19,CO19) -> 0 | S19: =P19-Q19 -> 0 | X19: =U19-V19 -> 0 | AD19: =AA19-AB19 -> 0 | AH19: =AE19-AF19 -> 0 | AN19: =AK19-AL19 -> 0 | AS19: =AP19-AQ19 -> 0 | AX19: =AU19-AV19 -> 0 | BC19: =AZ19-BA19 -> 0 | BI19: =BF19-BG19 -> 0 | BN19: =BK19-BL19 -> 0 | BS19: =BP19-BQ19 -> 0 | BX19: =BU19-BV19 -> 0 | CD19: =CA19-CB19 -> 0 | CI19: =CF19-CG19 -> 0 | CN19: =CK19-CL19 -> 0 | CS19: =CP19-CQ19 -> 0
A20: 11 | B20: 新規獲得件数 | J20: =SUM(P20,U20,Z20,AK20,AP20,AU20,BF20,BK20,BP20,CA20,CF20,CK20) -> 0 | K20: =SUM(Q20,V20,AA20,AL20,AQ20,AV20,BG20,BL20,BQ20,CB20,CG20,CL20) -> 0 | L20: =SUM(R20,W20,AB20,AM20,AR20,AW20,BH20,BM20,BR20,CC20,CH20,CM20) -> 0 | M20: =SUM(S20,X20,AC20,AN20,AS20,AX20,BI20,BN20,BS20,CD20,CI20,CN20) -> 0 | N20: =SUM(T20,Y20,AD20,AO20,AT20,AY20,BJ20,BO20,BT20,CE20,CJ20,CO20) -> 0 | S20: =P20-Q20 -> 0 | X20: =U20-V20 -> 0 | AD20: =AA20-AB20 -> 0 | AH20: =AE20-AF20 -> 0 | AN20: =AK20-AL20 -> 0 | AS20: =AP20-AQ20 -> 0 | AX20: =AU20-AV20 -> 0 | BC20: =AZ20-BA20 -> 0 | BI20: =BF20-BG20 -> 0 | BN20: =BK20-BL20 -> 0 | BS20: =BP20-BQ20 -> 0 | BX20: =BU20-BV20 -> 0 | CD20: =CA20-CB20 -> 0 | CI20: =CF20-CG20 -> 0 | CN20: =CK20-CL20 -> 0 | CS20: =CP20-CQ20 -> 0
A21: 12 | B21: 継続対象件数 | J21: =SUM(P21,U21,Z21,AK21,AP21,AU21,BF21,BK21,BP21,CA21,CF21,CK21) -> 0 | K21: =SUM(Q21,V21,AA21,AL21,AQ21,AV21,BG21,BL21,BQ21,CB21,CG21,CL21) -> 0 | L21: =SUM(R21,W21,AB21,AM21,AR21,AW21,BH21,BM21,BR21,CC21,CH21,CM21) -> 0 | M21: =SUM(S21,X21,AC21,AN21,AS21,AX21,BI21,BN21,BS21,CD21,CI21,CN21) -> 0 | N21: =SUM(T21,Y21,AD21,AO21,AT21,AY21,BJ21,BO21,BT21,CE21,CJ21,CO21) -> 0 | S21: =P21-Q21 -> 0 | X21: =U21-V21 -> 0 | AD21: =AA21-AB21 -> 0 | AH21: =AE21-AF21 -> 0 | AN21: =AK21-AL21 -> 0 | AS21: =AP21-AQ21 -> 0 | AX21: =AU21-AV21 -> 0 | BC21: =AZ21-BA21 -> 0 | BI21: =BF21-BG21 -> 0 | BN21: =BK21-BL21 -> 0 | BS21: =BP21-BQ21 -> 0 | BX21: =BU21-BV21 -> 0 | CD21: =CA21-CB21 -> 0 | CI21: =CF21-CG21 -> 0 | CN21: =CK21-CL21 -> 0 | CS21: =CP21-CQ21 -> 0
A22: 13 | B22: 継続件数 | J22: =SUM(P22,U22,Z22,AK22,AP22,AU22,BF22,BK22,BP22,CA22,CF22,CK22) -> 0 | K22: =SUM(Q22,V22,AA22,AL22,AQ22,AV22,BG22,BL22,BQ22,CB22,CG22,CL22) -> 0 | L22: =SUM(R22,W22,AB22,AM22,AR22,AW22,BH22,BM22,BR22,CC22,CH22,CM22) -> 0 | M22: =SUM(S22,X22,AC22,AN22,AS22,AX22,BI22,BN22,BS22,CD22,CI22,CN22) -> 0 | N22: =SUM(T22,Y22,AD22,AO22,AT22,AY22,BJ22,BO22,BT22,CE22,CJ22,CO22) -> 0 | S22: =P22-Q22 -> 0 | X22: =U22-V22 -> 0 | AD22: =AA22-AB22 -> 0 | AH22: =AE22-AF22 -> 0 | AN22: =AK22-AL22 -> 0 | AS22: =AP22-AQ22 -> 0 | AX22: =AU22-AV22 -> 0 | BC22: =AZ22-BA22 -> 0 | BI22: =BF22-BG22 -> 0 | BN22: =BK22-BL22 -> 0 | BS22: =BP22-BQ22 -> 0 | BX22: =BU22-BV22 -> 0 | CD22: =CA22-CB22 -> 0 | CI22: =CF22-CG22 -> 0 | CN22: =CK22-CL22 -> 0 | CS22: =CP22-CQ22 -> 0
A23: 14 | B23: 車両保険件数 | J23: =SUM(P23,U23,Z23,AK23,AP23,AU23,BF23,BK23,BP23,CA23,CF23,CK23) -> 0 | K23: =SUM(Q23,V23,AA23,AL23,AQ23,AV23,BG23,BL23,BQ23,CB23,CG23,CL23) -> 0 | L23: =SUM(R23,W23,AB23,AM23,AR23,AW23,BH23,BM23,BR23,CC23,CH23,CM23) -> 0 | M23: =SUM(S23,X23,AC23,AN23,AS23,AX23,BI23,BN23,BS23,CD23,CI23,CN23) -> 0 | N23: =SUM(T23,Y23,AD23,AO23,AT23,AY23,BJ23,BO23,BT23,CE23,CJ23,CO23) -> 0 | S23: =P23-Q23 -> 0 | X23: =U23-V23 -> 0 | AD23: =AA23-AB23 -> 0 | AH23: =AE23-AF23 -> 0 | AN23: =AK23-AL23 -> 0 | AS23: =AP23-AQ23 -> 0 | AX23: =AU23-AV23 -> 0 | BC23: =AZ23-BA23 -> 0 | BI23: =BF23-BG23 -> 0 | BN23: =BK23-BL23 -> 0 | BS23: =BP23-BQ23 -> 0 | BX23: =BU23-BV23 -> 0 | CD23: =CA23-CB23 -> 0 | CI23: =CF23-CG23 -> 0 | CN23: =CK23-CL23 -> 0 | CS23: =CP23-CQ23 -> 0
A24: 15 | B24: 収保 | J24: =SUM(P24,U24,Z24,AK24,AP24,AU24,BF24,BK24,BP24,CA24,CF24,CK24) -> 0 | K24: =SUM(Q24,V24,AA24,AL24,AQ24,AV24,BG24,BL24,BQ24,CB24,CG24,CL24) -> 0 | L24: =SUM(R24,W24,AB24,AM24,AR24,AW24,BH24,BM24,BR24,CC24,CH24,CM24) -> 0 | M24: =SUM(S24,X24,AC24,AN24,AS24,AX24,BI24,BN24,BS24,CD24,CI24,CN24) -> 0 | N24: =SUM(T24,Y24,AD24,AO24,AT24,AY24,BJ24,BO24,BT24,CE24,CJ24,CO24) -> 0 | S24: =P24-Q24 -> 0 | X24: =U24-V24 -> 0 | AD24: =AA24-AB24 -> 0 | AH24: =AE24-AF24 -> 0 | AN24: =AK24-AL24 -> 0 | AS24: =AP24-AQ24 -> 0 | AX24: =AU24-AV24 -> 0 | BC24: =AZ24-BA24 -> 0 | BI24: =BF24-BG24 -> 0 | BN24: =BK24-BL24 -> 0 | BS24: =BP24-BQ24 -> 0 | BX24: =BU24-BV24 -> 0 | CD24: =CA24-CB24 -> 0 | CI24: =CF24-CG24 -> 0 | CN24: =CK24-CL24 -> 0 | CS24: =CP24-CQ24 -> 0
A25: 16 | B25: 総限界利益 | C25: 総利益合計 | D25: 新車 | E25: 新車台数 | J25: =SUM(P25,U25,Z25,AK25,AP25,AU25,BF25,BK25,BP25,CA25,CF25,CK25) -> 0 | K25: =SUM(Q25,V25,AA25,AL25,AQ25,AV25,BG25,BL25,BQ25,CB25,CG25,CL25) -> 0 | L25: =SUM(R25,W25,AB25,AM25,AR25,AW25,BH25,BM25,BR25,CC25,CH25,CM25) -> 0 | M25: =SUM(S25,X25,AC25,AN25,AS25,AX25,BI25,BN25,BS25,CD25,CI25,CN25) -> 0 | N25: =SUM(T25,Y25,AD25,AO25,AT25,AY25,BJ25,BO25,BT25,CE25,CJ25,CO25) -> 0 | S25: =P25-Q25 -> 0 | X25: =U25-V25 -> 0 | AD25: =AA25-AB25 -> 0 | AH25: =AE25-AF25 -> 0 | AN25: =AK25-AL25 -> 0 | AS25: =AP25-AQ25 -> 0 | AX25: =AU25-AV25 -> 0 | BC25: =AZ25-BA25 -> 0 | BI25: =BF25-BG25 -> 0 | BN25: =BK25-BL25 -> 0 | BS25: =BP25-BQ25 -> 0 | BX25: =BU25-BV25 -> 0 | CD25: =CA25-CB25 -> 0 | CI25: =CF25-CG25 -> 0 | CN25: =CK25-CL25 -> 0 | CS25: =CP25-CQ25 -> 0
A26: 17 | E26: 売上金額（架装売上含む） | J26: =SUM(P26,U26,Z26,AK26,AP26,AU26,BF26,BK26,BP26,CA26,CF26,CK26) -> 0 | K26: =SUM(Q26,V26,AA26,AL26,AQ26,AV26,BG26,BL26,BQ26,CB26,CG26,CL26) -> 0 | L26: =SUM(R26,W26,AB26,AM26,AR26,AW26,BH26,BM26,BR26,CC26,CH26,CM26) -> 0 | M26: =SUM(S26,X26,AC26,AN26,AS26,AX26,BI26,BN26,BS26,CD26,CI26,CN26) -> 0 | N26: =SUM(T26,Y26,AD26,AO26,AT26,AY26,BJ26,BO26,BT26,CE26,CJ26,CO26) -> 0 | S26: =P26-Q26 -> 0 | X26: =U26-V26 -> 0 | AD26: =AA26-AB26 -> 0 | AH26: =AE26-AF26 -> 0 | AN26: =AK26-AL26 -> 0 | AS26: =AP26-AQ26 -> 0 | AX26: =AU26-AV26 -> 0 | BC26: =AZ26-BA26 -> 0 | BI26: =BF26-BG26 -> 0 | BN26: =BK26-BL26 -> 0 | BS26: =BP26-BQ26 -> 0 | BX26: =BU26-BV26 -> 0 | CD26: =CA26-CB26 -> 0 | CI26: =CF26-CG26 -> 0 | CN26: =CK26-CL26 -> 0 | CS26: =CP26-CQ26 -> 0
A27: 18 | F27: ＜内車両値引＞ | J27: =SUM(P27,U27,Z27,AK27,AP27,AU27,BF27,BK27,BP27,CA27,CF27,CK27) -> 0 | K27: =SUM(Q27,V27,AA27,AL27,AQ27,AV27,BG27,BL27,BQ27,CB27,CG27,CL27) -> 0 | L27: =SUM(R27,W27,AB27,AM27,AR27,AW27,BH27,BM27,BR27,CC27,CH27,CM27) -> 0 | M27: =SUM(S27,X27,AC27,AN27,AS27,AX27,BI27,BN27,BS27,CD27,CI27,CN27) -> 0 | N27: =SUM(T27,Y27,AD27,AO27,AT27,AY27,BJ27,BO27,BT27,CE27,CJ27,CO27) -> 0 | S27: =P27-Q27 -> 0 | X27: =U27-V27 -> 0 | AD27: =AA27-AB27 -> 0 | AH27: =AE27-AF27 -> 0 | AN27: =AK27-AL27 -> 0 | AS27: =AP27-AQ27 -> 0 | AX27: =AU27-AV27 -> 0 | BC27: =AZ27-BA27 -> 0 | BI27: =BF27-BG27 -> 0 | BN27: =BK27-BL27 -> 0 | BS27: =BP27-BQ27 -> 0 | BX27: =BU27-BV27 -> 0 | CD27: =CA27-CB27 -> 0 | CI27: =CF27-CG27 -> 0 | CN27: =CK27-CL27 -> 0 | CS27: =CP27-CQ27 -> 0
A28: 19 | F28: 車両本体利益 | J28: =SUM(P28,U28,Z28,AK28,AP28,AU28,BF28,BK28,BP28,CA28,CF28,CK28) -> 0 | K28: =SUM(Q28,V28,AA28,AL28,AQ28,AV28,BG28,BL28,BQ28,CB28,CG28,CL28) -> 0 | L28: =SUM(R28,W28,AB28,AM28,AR28,AW28,BH28,BM28,BR28,CC28,CH28,CM28) -> 0 | M28: =SUM(S28,X28,AC28,AN28,AS28,AX28,BI28,BN28,BS28,CD28,CI28,CN28) -> 0 | N28: =SUM(T28,Y28,AD28,AO28,AT28,AY28,BJ28,BO28,BT28,CE28,CJ28,CO28) -> 0 | S28: =P28-Q28 -> 0 | X28: =U28-V28 -> 0 | AD28: =AA28-AB28 -> 0 | AH28: =AE28-AF28 -> 0 | AN28: =AK28-AL28 -> 0 | AS28: =AP28-AQ28 -> 0 | AX28: =AU28-AV28 -> 0 | BC28: =AZ28-BA28 -> 0 | BI28: =BF28-BG28 -> 0 | BN28: =BK28-BL28 -> 0 | BS28: =BP28-BQ28 -> 0 | BX28: =BU28-BV28 -> 0 | CD28: =CA28-CB28 -> 0 | CI28: =CF28-CG28 -> 0 | CN28: =CK28-CL28 -> 0 | CS28: =CP28-CQ28 -> 0
A29: 20 | F29: 架装付属品利益 | J29: =SUM(P29,U29,Z29,AK29,AP29,AU29,BF29,BK29,BP29,CA29,CF29,CK29) -> 0 | K29: =SUM(Q29,V29,AA29,AL29,AQ29,AV29,BG29,BL29,BQ29,CB29,CG29,CL29) -> 0 | L29: =SUM(R29,W29,AB29,AM29,AR29,AW29,BH29,BM29,BR29,CC29,CH29,CM29) -> 0 | M29: =SUM(S29,X29,AC29,AN29,AS29,AX29,BI29,BN29,BS29,CD29,CI29,CN29) -> 0 | N29: =SUM(T29,Y29,AD29,AO29,AT29,AY29,BJ29,BO29,BT29,CE29,CJ29,CO29) -> 0 | S29: =P29-Q29 -> 0 | X29: =U29-V29 -> 0 | AD29: =AA29-AB29 -> 0 | AH29: =AE29-AF29 -> 0 | AN29: =AK29-AL29 -> 0 | AS29: =AP29-AQ29 -> 0 | AX29: =AU29-AV29 -> 0 | BC29: =AZ29-BA29 -> 0 | BI29: =BF29-BG29 -> 0 | BN29: =BK29-BL29 -> 0 | BS29: =BP29-BQ29 -> 0 | BX29: =BU29-BV29 -> 0 | CD29: =CA29-CB29 -> 0 | CI29: =CF29-CG29 -> 0 | CN29: =CK29-CL29 -> 0 | CS29: =CP29-CQ29 -> 0
A30: 21 | F30: 車両収入手数料 | J30: =SUM(P30,U30,Z30,AK30,AP30,AU30,BF30,BK30,BP30,CA30,CF30,CK30) -> 0 | K30: =SUM(Q30,V30,AA30,AL30,AQ30,AV30,BG30,BL30,BQ30,CB30,CG30,CL30) -> 0 | L30: =SUM(R30,W30,AB30,AM30,AR30,AW30,BH30,BM30,BR30,CC30,CH30,CM30) -> 0 | M30: =SUM(S30,X30,AC30,AN30,AS30,AX30,BI30,BN30,BS30,CD30,CI30,CN30) -> 0 | N30: =SUM(T30,Y30,AD30,AO30,AT30,AY30,BJ30,BO30,BT30,CE30,CJ30,CO30) -> 0 | S30: =P30-Q30 -> 0 | X30: =U30-V30 -> 0 | AD30: =AA30-AB30 -> 0 | AH30: =AE30-AF30 -> 0 | AN30: =AK30-AL30 -> 0 | AS30: =AP30-AQ30 -> 0 | AX30: =AU30-AV30 -> 0 | BC30: =AZ30-BA30 -> 0 | BI30: =BF30-BG30 -> 0 | BN30: =BK30-BL30 -> 0 | BS30: =BP30-BQ30 -> 0 | BX30: =BU30-BV30 -> 0 | CD30: =CA30-CB30 -> 0 | CI30: =CF30-CG30 -> 0 | CN30: =CK30-CL30 -> 0 | CS30: =CP30-CQ30 -> 0
A31: 22 | F31: 登録収入手数料 | J31: =SUM(P31,U31,Z31,AK31,AP31,AU31,BF31,BK31,BP31,CA31,CF31,CK31) -> 0 | K31: =SUM(Q31,V31,AA31,AL31,AQ31,AV31,BG31,BL31,BQ31,CB31,CG31,CL31) -> 0 | L31: =SUM(R31,W31,AB31,AM31,AR31,AW31,BH31,BM31,BR31,CC31,CH31,CM31) -> 0 | M31: =SUM(S31,X31,AC31,AN31,AS31,AX31,BI31,BN31,BS31,CD31,CI31,CN31) -> 0 | N31: =SUM(T31,Y31,AD31,AO31,AT31,AY31,BJ31,BO31,BT31,CE31,CJ31,CO31) -> 0 | S31: =P31-Q31 -> 0 | X31: =U31-V31 -> 0 | AD31: =AA31-AB31 -> 0 | AH31: =AE31-AF31 -> 0 | AN31: =AK31-AL31 -> 0 | AS31: =AP31-AQ31 -> 0 | AX31: =AU31-AV31 -> 0 | BC31: =AZ31-BA31 -> 0 | BI31: =BF31-BG31 -> 0 | BN31: =BK31-BL31 -> 0 | BS31: =BP31-BQ31 -> 0 | BX31: =BU31-BV31 -> 0 | CD31: =CA31-CB31 -> 0 | CI31: =CF31-CG31 -> 0 | CN31: =CK31-CL31 -> 0 | CS31: =CP31-CQ31 -> 0
A32: 23 | F32: クレジット利益 | J32: =SUM(P32,U32,Z32,AK32,AP32,AU32,BF32,BK32,BP32,CA32,CF32,CK32) -> 0 | K32: =SUM(Q32,V32,AA32,AL32,AQ32,AV32,BG32,BL32,BQ32,CB32,CG32,CL32) -> 0 | L32: =SUM(R32,W32,AB32,AM32,AR32,AW32,BH32,BM32,BR32,CC32,CH32,CM32) -> 0 | M32: =SUM(S32,X32,AC32,AN32,AS32,AX32,BI32,BN32,BS32,CD32,CI32,CN32) -> 0 | N32: =SUM(T32,Y32,AD32,AO32,AT32,AY32,BJ32,BO32,BT32,CE32,CJ32,CO32) -> 0 | S32: =P32-Q32 -> 0 | X32: =U32-V32 -> 0 | AD32: =AA32-AB32 -> 0 | AH32: =AE32-AF32 -> 0 | AN32: =AK32-AL32 -> 0 | AS32: =AP32-AQ32 -> 0 | AX32: =AU32-AV32 -> 0 | BC32: =AZ32-BA32 -> 0 | BI32: =BF32-BG32 -> 0 | BN32: =BK32-BL32 -> 0 | BS32: =BP32-BQ32 -> 0 | BX32: =BU32-BV32 -> 0 | CD32: =CA32-CB32 -> 0 | CI32: =CF32-CG32 -> 0 | CN32: =CK32-CL32 -> 0 | CS32: =CP32-CQ32 -> 0
A33: 24 | F33: 販売手数料 | J33: =SUM(P33,U33,Z33,AK33,AP33,AU33,BF33,BK33,BP33,CA33,CF33,CK33) -> 0 | K33: =SUM(Q33,V33,AA33,AL33,AQ33,AV33,BG33,BL33,BQ33,CB33,CG33,CL33) -> 0 | L33: =SUM(R33,W33,AB33,AM33,AR33,AW33,BH33,BM33,BR33,CC33,CH33,CM33) -> 0 | M33: =SUM(S33,X33,AC33,AN33,AS33,AX33,BI33,BN33,BS33,CD33,CI33,CN33) -> 0 | N33: =SUM(T33,Y33,AD33,AO33,AT33,AY33,BJ33,BO33,BT33,CE33,CJ33,CO33) -> 0 | S33: =P33-Q33 -> 0 | X33: =U33-V33 -> 0 | AD33: =AA33-AB33 -> 0 | AH33: =AE33-AF33 -> 0 | AN33: =AK33-AL33 -> 0 | AS33: =AP33-AQ33 -> 0 | AX33: =AU33-AV33 -> 0 | BC33: =AZ33-BA33 -> 0 | BI33: =BF33-BG33 -> 0 | BN33: =BK33-BL33 -> 0 | BS33: =BP33-BQ33 -> 0 | BX33: =BU33-BV33 -> 0 | CD33: =CA33-CB33 -> 0 | CI33: =CF33-CG33 -> 0 | CN33: =CK33-CL33 -> 0 | CS33: =CP33-CQ33 -> 0
A34: 25 | E34: 新車総粗利 | J34: =SUM(P34,U34,Z34,AK34,AP34,AU34,BF34,BK34,BP34,CA34,CF34,CK34) -> 0 | K34: =SUM(Q34,V34,AA34,AL34,AQ34,AV34,BG34,BL34,BQ34,CB34,CG34,CL34) -> 0 | L34: =SUM(R34,W34,AB34,AM34,AR34,AW34,BH34,BM34,BR34,CC34,CH34,CM34) -> 0 | M34: =SUM(S34,X34,AC34,AN34,AS34,AX34,BI34,BN34,BS34,CD34,CI34,CN34) -> 0 | N34: =SUM(T34,Y34,AD34,AO34,AT34,AY34,BJ34,BO34,BT34,CE34,CJ34,CO34) -> 0 | S34: =P34-Q34 -> 0 | X34: =U34-V34 -> 0 | AD34: =AA34-AB34 -> 0 | AH34: =AE34-AF34 -> 0 | AN34: =AK34-AL34 -> 0 | AS34: =AP34-AQ34 -> 0 | AX34: =AU34-AV34 -> 0 | BC34: =AZ34-BA34 -> 0 | BI34: =BF34-BG34 -> 0 | BN34: =BK34-BL34 -> 0 | BS34: =BP34-BQ34 -> 0 | BX34: =BU34-BV34 -> 0 | CD34: =CA34-CB34 -> 0 | CI34: =CF34-CG34 -> 0 | CN34: =CK34-CL34 -> 0 | CS34: =CP34-CQ34 -> 0
A35: 26 | E35: 販売費 | F35: 販手・サービス・雑費 | J35: =SUM(P35,U35,Z35,AK35,AP35,AU35,BF35,BK35,BP35,CA35,CF35,CK35) -> 0 | K35: =SUM(Q35,V35,AA35,AL35,AQ35,AV35,BG35,BL35,BQ35,CB35,CG35,CL35) -> 0 | L35: =SUM(R35,W35,AB35,AM35,AR35,AW35,BH35,BM35,BR35,CC35,CH35,CM35) -> 0 | M35: =SUM(S35,X35,AC35,AN35,AS35,AX35,BI35,BN35,BS35,CD35,CI35,CN35) -> 0 | N35: =SUM(T35,Y35,AD35,AO35,AT35,AY35,BJ35,BO35,BT35,CE35,CJ35,CO35) -> 0 | S35: =P35-Q35 -> 0 | X35: =U35-V35 -> 0 | AD35: =AA35-AB35 -> 0 | AH35: =AE35-AF35 -> 0 | AN35: =AK35-AL35 -> 0 | AS35: =AP35-AQ35 -> 0 | AX35: =AU35-AV35 -> 0 | BC35: =AZ35-BA35 -> 0 | BI35: =BF35-BG35 -> 0 | BN35: =BK35-BL35 -> 0 | BS35: =BP35-BQ35 -> 0 | BX35: =BU35-BV35 -> 0 | CD35: =CA35-CB35 -> 0 | CI35: =CF35-CG35 -> 0 | CN35: =CK35-CL35 -> 0 | CS35: =CP35-CQ35 -> 0
A36: 27 | F36: 納車費・運送保管費 | J36: =SUM(P36,U36,Z36,AK36,AP36,AU36,BF36,BK36,BP36,CA36,CF36,CK36) -> 0 | K36: =SUM(Q36,V36,AA36,AL36,AQ36,AV36,BG36,BL36,BQ36,CB36,CG36,CL36) -> 0 | L36: =SUM(R36,W36,AB36,AM36,AR36,AW36,BH36,BM36,BR36,CC36,CH36,CM36) -> 0 | M36: =SUM(S36,X36,AC36,AN36,AS36,AX36,BI36,BN36,BS36,CD36,CI36,CN36) -> 0 | N36: =SUM(T36,Y36,AD36,AO36,AT36,AY36,BJ36,BO36,BT36,CE36,CJ36,CO36) -> 0 | S36: =P36-Q36 -> 0 | X36: =U36-V36 -> 0 | AD36: =AA36-AB36 -> 0 | AH36: =AE36-AF36 -> 0 | AN36: =AK36-AL36 -> 0 | AS36: =AP36-AQ36 -> 0 | AX36: =AU36-AV36 -> 0 | BC36: =AZ36-BA36 -> 0 | BI36: =BF36-BG36 -> 0 | BN36: =BK36-BL36 -> 0 | BS36: =BP36-BQ36 -> 0 | BX36: =BU36-BV36 -> 0 | CD36: =CA36-CB36 -> 0 | CI36: =CF36-CG36 -> 0 | CN36: =CK36-CL36 -> 0 | CS36: =CP36-CQ36 -> 0
A37: 28 | F37: 広告宣伝費 | J37: =SUM(P37,U37,Z37,AK37,AP37,AU37,BF37,BK37,BP37,CA37,CF37,CK37) -> 0 | K37: =SUM(Q37,V37,AA37,AL37,AQ37,AV37,BG37,BL37,BQ37,CB37,CG37,CL37) -> 0 | L37: =SUM(R37,W37,AB37,AM37,AR37,AW37,BH37,BM37,BR37,CC37,CH37,CM37) -> 0 | M37: =SUM(S37,X37,AC37,AN37,AS37,AX37,BI37,BN37,BS37,CD37,CI37,CN37) -> 0 | N37: =SUM(T37,Y37,AD37,AO37,AT37,AY37,BJ37,BO37,BT37,CE37,CJ37,CO37) -> 0 | S37: =P37-Q37 -> 0 | X37: =U37-V37 -> 0 | AD37: =AA37-AB37 -> 0 | AH37: =AE37-AF37 -> 0 | AN37: =AK37-AL37 -> 0 | AS37: =AP37-AQ37 -> 0 | AX37: =AU37-AV37 -> 0 | BC37: =AZ37-BA37 -> 0 | BI37: =BF37-BG37 -> 0 | BN37: =BK37-BL37 -> 0 | BS37: =BP37-BQ37 -> 0 | BX37: =BU37-BV37 -> 0 | CD37: =CA37-CB37 -> 0 | CI37: =CF37-CG37 -> 0 | CN37: =CK37-CL37 -> 0 | CS37: =CP37-CQ37 -> 0
A38: 29 | F38: デモカー・代車費 | J38: =SUM(P38,U38,Z38,AK38,AP38,AU38,BF38,BK38,BP38,CA38,CF38,CK38) -> 0 | K38: =SUM(Q38,V38,AA38,AL38,AQ38,AV38,BG38,BL38,BQ38,CB38,CG38,CL38) -> 0 | L38: =SUM(R38,W38,AB38,AM38,AR38,AW38,BH38,BM38,BR38,CC38,CH38,CM38) -> 0 | M38: =SUM(S38,X38,AC38,AN38,AS38,AX38,BI38,BN38,BS38,CD38,CI38,CN38) -> 0 | N38: =SUM(T38,Y38,AD38,AO38,AT38,AY38,BJ38,BO38,BT38,CE38,CJ38,CO38) -> 0 | S38: =P38-Q38 -> 0 | X38: =U38-V38 -> 0 | AD38: =AA38-AB38 -> 0 | AH38: =AE38-AF38 -> 0 | AN38: =AK38-AL38 -> 0 | AS38: =AP38-AQ38 -> 0 | AX38: =AU38-AV38 -> 0 | BC38: =AZ38-BA38 -> 0 | BI38: =BF38-BG38 -> 0 | BN38: =BK38-BL38 -> 0 | BS38: =BP38-BQ38 -> 0 | BX38: =BU38-BV38 -> 0 | CD38: =CA38-CB38 -> 0 | CI38: =CF38-CG38 -> 0 | CN38: =CK38-CL38 -> 0 | CS38: =CP38-CQ38 -> 0
A39: 30 | F39: 本部負担金 | J39: =SUM(P39,U39,Z39,AK39,AP39,AU39,BF39,BK39,BP39,CA39,CF39,CK39) -> 0 | K39: =SUM(Q39,V39,AA39,AL39,AQ39,AV39,BG39,BL39,BQ39,CB39,CG39,CL39) -> 0 | L39: =SUM(R39,W39,AB39,AM39,AR39,AW39,BH39,BM39,BR39,CC39,CH39,CM39) -> 0 | M39: =SUM(S39,X39,AC39,AN39,AS39,AX39,BI39,BN39,BS39,CD39,CI39,CN39) -> 0 | N39: =SUM(T39,Y39,AD39,AO39,AT39,AY39,BJ39,BO39,BT39,CE39,CJ39,CO39) -> 0 | S39: =P39-Q39 -> 0 | X39: =U39-V39 -> 0 | AD39: =AA39-AB39 -> 0 | AH39: =AE39-AF39 -> 0 | AN39: =AK39-AL39 -> 0 | AS39: =AP39-AQ39 -> 0 | AX39: =AU39-AV39 -> 0 | BC39: =AZ39-BA39 -> 0 | BI39: =BF39-BG39 -> 0 | BN39: =BK39-BL39 -> 0 | BS39: =BP39-BQ39 -> 0 | BX39: =BU39-BV39 -> 0 | CD39: =CA39-CB39 -> 0 | CI39: =CF39-CG39 -> 0 | CN39: =CK39-CL39 -> 0 | CS39: =CP39-CQ39 -> 0
A40: 31 | F40: 小計 | J40: =SUM(P40,U40,Z40,AK40,AP40,AU40,BF40,BK40,BP40,CA40,CF40,CK40) -> 0 | K40: =SUM(Q40,V40,AA40,AL40,AQ40,AV40,BG40,BL40,BQ40,CB40,CG40,CL40) -> 0 | L40: =SUM(R40,W40,AB40,AM40,AR40,AW40,BH40,BM40,BR40,CC40,CH40,CM40) -> 0 | M40: =SUM(S40,X40,AC40,AN40,AS40,AX40,BI40,BN40,BS40,CD40,CI40,CN40) -> 0 | N40: =SUM(T40,Y40,AD40,AO40,AT40,AY40,BJ40,BO40,BT40,CE40,CJ40,CO40) -> 0 | S40: =P40-Q40 -> 0 | X40: =U40-V40 -> 0 | AD40: =AA40-AB40 -> 0 | AH40: =AE40-AF40 -> 0 | AN40: =AK40-AL40 -> 0 | AS40: =AP40-AQ40 -> 0 | AX40: =AU40-AV40 -> 0 | BC40: =AZ40-BA40 -> 0 | BI40: =BF40-BG40 -> 0 | BN40: =BK40-BL40 -> 0 | BS40: =BP40-BQ40 -> 0 | BX40: =BU40-BV40 -> 0 | CD40: =CA40-CB40 -> 0 | CI40: =CF40-CG40 -> 0 | CN40: =CK40-CL40 -> 0 | CS40: =CP40-CQ40 -> 0
A41: 32 | E41: 新車限界利益 | J41: =SUM(P41,U41,Z41,AK41,AP41,AU41,BF41,BK41,BP41,CA41,CF41,CK41) -> 0 | K41: =SUM(Q41,V41,AA41,AL41,AQ41,AV41,BG41,BL41,BQ41,CB41,CG41,CL41) -> 0 | L41: =SUM(R41,W41,AB41,AM41,AR41,AW41,BH41,BM41,BR41,CC41,CH41,CM41) -> 0 | M41: =SUM(S41,X41,AC41,AN41,AS41,AX41,BI41,BN41,BS41,CD41,CI41,CN41) -> 0 | N41: =SUM(T41,Y41,AD41,AO41,AT41,AY41,BJ41,BO41,BT41,CE41,CJ41,CO41) -> 0 | S41: =P41-Q41 -> 0 | X41: =U41-V41 -> 0 | AD41: =AA41-AB41 -> 0 | AH41: =AE41-AF41 -> 0 | AN41: =AK41-AL41 -> 0 | AS41: =AP41-AQ41 -> 0 | AX41: =AU41-AV41 -> 0 | BC41: =AZ41-BA41 -> 0 | BI41: =BF41-BG41 -> 0 | BN41: =BK41-BL41 -> 0 | BS41: =BP41-BQ41 -> 0 | BX41: =BU41-BV41 -> 0 | CD41: =CA41-CB41 -> 0 | CI41: =CF41-CG41 -> 0 | CN41: =CK41-CL41 -> 0 | CS41: =CP41-CQ41 -> 0
A42: 33 | D42: 中古車 | E42: 直売 | F42: 直売台数 | J42: =SUM(P42,U42,Z42,AK42,AP42,AU42,BF42,BK42,BP42,CA42,CF42,CK42) -> 0 | K42: =SUM(Q42,V42,AA42,AL42,AQ42,AV42,BG42,BL42,BQ42,CB42,CG42,CL42) -> 0 | L42: =SUM(R42,W42,AB42,AM42,AR42,AW42,BH42,BM42,BR42,CC42,CH42,CM42) -> 0 | M42: =SUM(S42,X42,AC42,AN42,AS42,AX42,BI42,BN42,BS42,CD42,CI42,CN42) -> 0 | N42: =SUM(T42,Y42,AD42,AO42,AT42,AY42,BJ42,BO42,BT42,CE42,CJ42,CO42) -> 0 | S42: =P42-Q42 -> 0 | X42: =U42-V42 -> 0 | AD42: =AA42-AB42 -> 0 | AH42: =AE42-AF42 -> 0 | AN42: =AK42-AL42 -> 0 | AS42: =AP42-AQ42 -> 0 | AX42: =AU42-AV42 -> 0 | BC42: =AZ42-BA42 -> 0 | BI42: =BF42-BG42 -> 0 | BN42: =BK42-BL42 -> 0 | BS42: =BP42-BQ42 -> 0 | BX42: =BU42-BV42 -> 0 | CD42: =CA42-CB42 -> 0 | CI42: =CF42-CG42 -> 0 | CN42: =CK42-CL42 -> 0 | CS42: =CP42-CQ42 -> 0
A43: 34 | F43: 売上金額 | J43: =SUM(P43,U43,Z43,AK43,AP43,AU43,BF43,BK43,BP43,CA43,CF43,CK43) -> 0 | K43: =SUM(Q43,V43,AA43,AL43,AQ43,AV43,BG43,BL43,BQ43,CB43,CG43,CL43) -> 0 | L43: =SUM(R43,W43,AB43,AM43,AR43,AW43,BH43,BM43,BR43,CC43,CH43,CM43) -> 0 | M43: =SUM(S43,X43,AC43,AN43,AS43,AX43,BI43,BN43,BS43,CD43,CI43,CN43) -> 0 | N43: =SUM(T43,Y43,AD43,AO43,AT43,AY43,BJ43,BO43,BT43,CE43,CJ43,CO43) -> 0 | S43: =P43-Q43 -> 0 | X43: =U43-V43 -> 0 | AD43: =AA43-AB43 -> 0 | AH43: =AE43-AF43 -> 0 | AN43: =AK43-AL43 -> 0 | AS43: =AP43-AQ43 -> 0 | AX43: =AU43-AV43 -> 0 | BC43: =AZ43-BA43 -> 0 | BI43: =BF43-BG43 -> 0 | BN43: =BK43-BL43 -> 0 | BS43: =BP43-BQ43 -> 0 | BX43: =BU43-BV43 -> 0 | CD43: =CA43-CB43 -> 0 | CI43: =CF43-CG43 -> 0 | CN43: =CK43-CL43 -> 0 | CS43: =CP43-CQ43 -> 0
...

Sheet サービス
B1: 予算表
B3: 期：
B5: 部署：
B7: 項目 | J7: 年間計 | P7: １０月 | U7: １１月 | Z7: １２月 | AE7: １０月～１２月合計 | AK7: １月 | AP7: ２月 | AU7: ３月 | AZ7: １月～３月合計 | BF7: ４月 | BK7: ５月 | BP7: ６月 | BU7: ４月～６月合計 | CA7: ７月 | CF7: ８月 | CK7: ９月 | CP7: ７月～９月合計
A8: LineNo
J9: 計画 | K9: 前年実績 | L9: 指標 | M9: 計画差 | N9: 前年比 | P9: 計画 | Q9: 前年実績 | R9: 指標 | S9: 計画差 | T9: 前年比 | U9: 計画 | V9: 前年実績 | W9: 指標 | X9: 計画差 | Y9: 前年比 | Z9: 計画 | AA9: 前年実績 | AB9: 指標 | AC9: 計画差 | AD9: 前年比 | AE9: 計画 | AF9: 前年実績 | AG9: 指標 | AH9: 計画差 | AI9: 前年比 | AK9: 計画 | AL9: 前年実績 | AM9: 指標 | AN9: 計画差 | AO9: 前年比 | AP9: 計画 | AQ9: 前年実績 | AR9: 指標 | AS9: 計画差 | AT9: 前年比 | AU9: 計画 | AV9: 前年実績 | AW9: 指標 | AX9: 計画差 | AY9: 前年比 | AZ9: 計画 | BA9: 前年実績 | BB9: 指標 | BC9: 計画差 | BD9: 前年比 | BF9: 計画 | BG9: 前年実績 | BH9: 指標 | BI9: 計画差 | BJ9: 前年比 | BK9: 計画 | BL9: 前年実績 | BM9: 指標 | BN9: 計画差 | BO9: 前年比 | BP9: 計画 | BQ9: 前年実績 | BR9: 指標 | BS9: 計画差 | BT9: 前年比 | BU9: 計画 | BV9: 前年実績 | BW9: 指標 | BX9: 計画差 | BY9: 前年比 | CA9: 計画 | CB9: 前年実績 | CC9: 指標 | CD9: 計画差 | CE9: 前年比 | CF9: 計画 | CG9: 前年実績 | CH9: 指標 | CI9: 計画差 | CJ9: 前年比 | CK9: 計画 | CL9: 前年実績 | CM9: 指標 | CN9: 計画差 | CO9: 前年比 | CP9: 計画 | CQ9: 前年実績 | CR9: 指標 | CS9: 計画差 | CT9: 前年比
A10: 1 | B10: 営業スタッフ数 | J10: =SUM(P10,U10,Z10,AK10,AP10,AU10,BF10,BK10,BP10,CA10,CF10,CK10) -> 0 | K10: =SUM(Q10,V10,AA10,AL10,AQ10,AV10,BG10,BL10,BQ10,CB10,CG10,CL10) -> 0 | L10: =SUM(R10,W10,AB10,AM10,AR10,AW10,BH10,BM10,BR10,CC10,CH10,CM10) -> 0 | M10: =SUM(S10,X10,AC10,AN10,AS10,AX10,BI10,BN10,BS10,CD10,CI10,CN10) -> 0 | N10: =SUM(T10,Y10,AD10,AO10,AT10,AY10,BJ10,BO10,BT10,CE10,CJ10,CO10) -> 0 | S10: =P10-Q10 -> 0 | X10: =U10-V10 -> 0 | AD10: =AA10-AB10 -> 0 | AH10: =AE10-AF10 -> 0 | AN10: =AK10-AL10 -> 0 | AS10: =AP10-AQ10 -> 0 | AX10: =AU10-AV10 -> 0 | BC10: =AZ10-BA10 -> 0 | BI10: =BF10-BG10 -> 0 | BN10: =BK10-BL10 -> 0 | BS10: =BP10-BQ10 -> 0 | BX10: =BU10-BV10 -> 0 | CD10: =CA10-CB10 -> 0 | CI10: =CF10-CG10 -> 0 | CN10: =CK10-CL10 -> 0 | CS10: =CP10-CQ10 -> 0
A11: 2 | B11: 自新直顧客数 | J11: =SUM(P11,U11,Z11,AK11,AP11,AU11,BF11,BK11,BP11,CA11,CF11,CK11) -> 0 | K11: =SUM(Q11,V11,AA11,AL11,AQ11,AV11,BG11,BL11,BQ11,CB11,CG11,CL11) -> 0 | L11: =SUM(R11,W11,AB11,AM11,AR11,AW11,BH11,BM11,BR11,CC11,CH11,CM11) -> 0 | M11: =SUM(S11,X11,AC11,AN11,AS11,AX11,BI11,BN11,BS11,CD11,CI11,CN11) -> 0 | N11: =SUM(T11,Y11,AD11,AO11,AT11,AY11,BJ11,BO11,BT11,CE11,CJ11,CO11) -> 0 | S11: =P11-Q11 -> 0 | X11: =U11-V11 -> 0 | AD11: =AA11-AB11 -> 0 | AH11: =AE11-AF11 -> 0 | AN11: =AK11-AL11 -> 0 | AS11: =AP11-AQ11 -> 0 | AX11: =AU11-AV11 -> 0 | BC11: =AZ11-BA11 -> 0 | BI11: =BF11-BG11 -> 0 | BN11: =BK11-BL11 -> 0 | BS11: =BP11-BQ11 -> 0 | BX11: =BU11-BV11 -> 0 | CD11: =CA11-CB11 -> 0 | CI11: =CF11-CG11 -> 0 | CN11: =CK11-CL11 -> 0 | CS11: =CP11-CQ11 -> 0
A12: 3 | B12: 顧客代替台数 | J12: =SUM(P12,U12,Z12,AK12,AP12,AU12,BF12,BK12,BP12,CA12,CF12,CK12) -> 0 | K12: =SUM(Q12,V12,AA12,AL12,AQ12,AV12,BG12,BL12,BQ12,CB12,CG12,CL12) -> 0 | L12: =SUM(R12,W12,AB12,AM12,AR12,AW12,BH12,BM12,BR12,CC12,CH12,CM12) -> 0 | M12: =SUM(S12,X12,AC12,AN12,AS12,AX12,BI12,BN12,BS12,CD12,CI12,CN12) -> 0 | N12: =SUM(T12,Y12,AD12,AO12,AT12,AY12,BJ12,BO12,BT12,CE12,CJ12,CO12) -> 0 | S12: =P12-Q12 -> 0 | X12: =U12-V12 -> 0 | AD12: =AA12-AB12 -> 0 | AH12: =AE12-AF12 -> 0 | AN12: =AK12-AL12 -> 0 | AS12: =AP12-AQ12 -> 0 | AX12: =AU12-AV12 -> 0 | BC12: =AZ12-BA12 -> 0 | BI12: =BF12-BG12 -> 0 | BN12: =BK12-BL12 -> 0 | BS12: =BP12-BQ12 -> 0 | BX12: =BU12-BV12 -> 0 | CD12: =CA12-CB12 -> 0 | CI12: =CF12-CG12 -> 0 | CN12: =CK12-CL12 -> 0 | CS12: =CP12-CQ12 -> 0
A13: 4 | B13: 自中直顧客数 | J13: =SUM(P13,U13,Z13,AK13,AP13,AU13,BF13,BK13,BP13,CA13,CF13,CK13) -> 0 | K13: =SUM(Q13,V13,AA13,AL13,AQ13,AV13,BG13,BL13,BQ13,CB13,CG13,CL13) -> 0 | L13: =SUM(R13,W13,AB13,AM13,AR13,AW13,BH13,BM13,BR13,CC13,CH13,CM13) -> 0 | M13: =SUM(S13,X13,AC13,AN13,AS13,AX13,BI13,BN13,BS13,CD13,CI13,CN13) -> 0 | N13: =SUM(T13,Y13,AD13,AO13,AT13,AY13,BJ13,BO13,BT13,CE13,CJ13,CO13) -> 0 | S13: =P13-Q13 -> 0 | X13: =U13-V13 -> 0 | AD13: =AA13-AB13 -> 0 | AH13: =AE13-AF13 -> 0 | AN13: =AK13-AL13 -> 0 | AS13: =AP13-AQ13 -> 0 | AX13: =AU13-AV13 -> 0 | BC13: =AZ13-BA13 -> 0 | BI13: =BF13-BG13 -> 0 | BN13: =BK13-BL13 -> 0 | BS13: =BP13-BQ13 -> 0 | BX13: =BU13-BV13 -> 0 | CD13: =CA13-CB13 -> 0 | CI13: =CF13-CG13 -> 0 | CN13: =CK13-CL13 -> 0 | CS13: =CP13-CQ13 -> 0
